<?xml version="1.0" ?>
<!-- =================================================================================== -->
<!-- |    This document was autogenerated by xacro from rb1_arm_standalone.urdf.xacro  | -->
<!-- |    EDITING THIS FILE BY HAND IS NOT RECOMMENDED                                 | -->
<!-- =================================================================================== -->
<robot name="rb1_arm" xmlns:xacro="http://ros.org/wiki/xacro">
  <!-- Used for fixing robot to Gazebo 'base_link' -->
  <link name="world"/>
  <joint name="fwf" type="fixed">
    <parent link="world"/>
    <child link="base_link_rb1_arm"/>
  </joint>
  <!-- ***************** -->
  <!-- Imported elements -->
  <!-- ***************** -->
  <!-- First we import all posible elements defined in the urdf.xacro files. All these elements are defined as macro:xacros -->
  <!-- Import RB1 arm elements -->
  <gazebo reference="base_link_rb1_arm">
    <material>Gazebo/FlatBlack</material>
    <turnGravityOff>false</turnGravityOff>
  </gazebo>
  <gazebo reference="link01_rb1_arm">
    <material>Gazebo/Gray</material>
    <turnGravityOff>false</turnGravityOff>
  </gazebo>
  <gazebo reference="motor01_rb1_arm">
    <material>Gazebo/Black</material>
    <turnGravityOff>false</turnGravityOff>
  </gazebo>
  <gazebo reference="link12_rb1_arm">
    <material>Gazebo/Gray</material>
    <turnGravityOff>false</turnGravityOff>
  </gazebo>
  <gazebo reference="motor12_rb1_arm">
    <material>Gazebo/Black</material>
    <turnGravityOff>false</turnGravityOff>
  </gazebo>
  <gazebo reference="link23_rb1_arm">
    <material>Gazebo/Gray</material>
    <turnGravityOff>false</turnGravityOff>
  </gazebo>
  <gazebo reference="motor23_rb1_arm">
    <material>Gazebo/Black</material>
    <turnGravityOff>false</turnGravityOff>
  </gazebo>
  <gazebo reference="link34_rb1_arm">
    <material>Gazebo/Gray</material>
    <turnGravityOff>false</turnGravityOff>
  </gazebo>
  <gazebo reference="motor34_rb1_arm">
    <material>Gazebo/Black</material>
    <turnGravityOff>false</turnGravityOff>
  </gazebo>
  <gazebo reference="link45_rb1_arm">
    <material>Gazebo/Gray</material>
    <turnGravityOff>false</turnGravityOff>
  </gazebo>
  <gazebo reference="motor45_rb1_arm">
    <material>Gazebo/Black</material>
    <turnGravityOff>false</turnGravityOff>
  </gazebo>
  <gazebo reference="link56_rb1_arm">
    <material>Gazebo/Gray</material>
    <turnGravityOff>false</turnGravityOff>
  </gazebo>
  <gazebo reference="motor56_rb1_arm">
    <material>Gazebo/Black</material>
    <turnGravityOff>false</turnGravityOff>
  </gazebo>
  <gazebo reference="link67_rb1_arm">
    <material>Gazebo/Gray</material>
    <turnGravityOff>false</turnGravityOff>
  </gazebo>
  <gazebo reference="motor67_rb1_arm">
    <material>Gazebo/Black</material>
    <turnGravityOff>false</turnGravityOff>
  </gazebo>
  <gazebo reference="end_effector_rb1_arm">
    <material>Gazebo/Gray</material>
    <turnGravityOff>false</turnGravityOff>
  </gazebo>
  <!-- Import all available sensors -->
  <!-- xacro:include filename="$(find rb1_arm_description)/urdf/sensors/all_sensors.urdf.xacro" / -->
  <!-- ***************** -->
  <!-- Global parameters -->
  <!-- ***************** -->
  <!-- Flag to select the high or low quality model -->
  <!-- RB-1 arm -->
  <xacro:property name="PI" value="3.1415926535897931"/>
  <link name="base_link_rb1_arm">
    </link>
  <joint name="j1_rb1_arm" type="fixed">
    <origin rpy="0.0 0.0 0.0" xyz="0.0 0.0 0.0"/>
    <parent link="base_link_rb1_arm"/>
    <child link="link01_rb1_arm"/>
    <axis xyz="0 0 0"/>
  </joint>
  <link name="link01_rb1_arm">
    <inertial>
      <mass value="0.506"/>
      <origin xyz="-0.05161 0 -0.003"/>
      <inertia ixx="0.0014526484" ixy="0.0" ixz="-8.792613e-005" iyx="0.0" iyy="0.0018217854" iyz="0.0" izz="0.0008987159"/>
    </inertial>
    <visual>
      <origin rpy="0 0 0" xyz="0 0 0"/>
      <geometry>
        <mesh filename="package://rb1_arm_description/meshes/arms/armRB1_1_link.dae"/>
      </geometry>
      <material name="darkgrey">
        <color rgba="0.1 0.1 0.1 1"/>
      </material>
    </visual>
    <collision>
      <origin rpy="0 0 0 " xyz="0 0 0"/>
      <geometry>
        <mesh filename="package://rb1_arm_description/meshes/arms/armRB1_1_link.dae"/>
      </geometry>
    </collision>
  </link>
  <link name="motor01_rb1_arm">
    <inertial>
      <mass value="0.855"/>
      <origin xyz="0 0 0.00693"/>
      <!--inertia  ixx="0.01" ixy="0.0"  ixz="0.0"  iyy="0.01"  iyz="0.0"  izz="0.01" /-->
      <inertia ixx="0.001211476" ixy="0.0" ixz="6.05332e-006" iyy="0.001211334" iyz="0.0" izz="0.0003787678"/>
    </inertial>
    <visual>
      <origin rpy="0 0 0" xyz="0 0 0"/>
      <geometry>
        <mesh filename="package://rb1_arm_description/meshes/arms/armRB1_1_motor.dae"/>
      </geometry>
      <material name="darkgrey">
        <color rgba="0.1 0.1 0.1 1"/>
      </material>
    </visual>
    <collision>
      <origin rpy="0 0 0 " xyz="0 0 0"/>
      <geometry>
        <mesh filename="package://rb1_arm_description/meshes/arms/armRB1_1_motor.dae"/>
      </geometry>
    </collision>
  </link>
  <joint name="j01m_rb1_arm" type="fixed">
    <origin rpy="0.0 0.0 0.0" xyz="0.0 0.0 0.0"/>
    <parent link="link01_rb1_arm"/>
    <child link="motor01_rb1_arm"/>
    <axis xyz="0 0 0"/>
  </joint>
  <link name="link12_rb1_arm">
    <inertial>
      <mass value="0.7"/>
      <origin xyz="0.07155 0.00229 -0.00028"/>
      <inertia ixx="0.0018430902" ixy="0.0001075379" ixz="2.683183e-005" iyy="0.0023530852" iyz="4.5192e-007" izz="0.0016327528"/>
    </inertial>
    <visual>
      <origin rpy="0 0 0" xyz="0 0 0"/>
      <geometry>
        <mesh filename="package://rb1_arm_description/meshes/arms/armRB1_12_link.dae"/>
      </geometry>
      <material name="darkgrey">
        <color rgba="0.1 0.1 0.1 1"/>
      </material>
    </visual>
    <collision>
      <origin rpy="0 0 0 " xyz="0 0 0"/>
      <geometry>
        <mesh filename="package://rb1_arm_description/meshes/arms/armRB1_12_link.dae"/>
      </geometry>
    </collision>
  </link>
  <link name="motor12_rb1_arm">
    <inertial>
      <mass value="0.855"/>
      <origin xyz="0.13488 -0.00693 0"/>
      <inertia ixx="0.001211476" ixy="-6.05332e-006" ixz="0.0" iyy="0.0003787678" iyz="0.0" izz="0.001211334"/>
    </inertial>
    <visual>
      <origin rpy="0 0 0" xyz="0 0 0"/>
      <geometry>
        <mesh filename="package://rb1_arm_description/meshes/arms/armRB1_12_motor.dae"/>
      </geometry>
      <material name="darkgrey">
        <color rgba="0.1 0.1 0.1 1"/>
      </material>
    </visual>
    <collision>
      <origin rpy="0 0 0 " xyz="0 0 0"/>
      <geometry>
        <mesh filename="package://rb1_arm_description/meshes/arms/armRB1_12_motor.dae"/>
      </geometry>
    </collision>
  </link>
  <joint name="j12m_rb1_arm" type="fixed">
    <origin rpy="0.0 0.0 0.0" xyz="0.0 0.0 0.0"/>
    <parent link="link12_rb1_arm"/>
    <child link="motor12_rb1_arm"/>
    <axis xyz="0 0 0"/>
  </joint>
  <joint name="j1" type="revolute">
    <origin rpy="0.0 0.0 0.0" xyz="0 0 0"/>
    <parent link="link01_rb1_arm"/>
    <child link="link12_rb1_arm"/>
    <axis xyz="0 0 -1"/>
    <limit effort="60.0" lower="-1.570796327" upper="1.570796327" velocity="2.9217"/>
    <dynamics damping="0.7" friction="0.5"/>
  </joint>
  <transmission name="j1_trans">
    <type>transmission_interface/SimpleTransmission</type>
    <joint name="j1"/>
    <actuator name="j1_motor">
      <hardwareInterface>EffortJointInterface</hardwareInterface>
      <mechanicalReduction>502.0</mechanicalReduction>
      <motorTorqueConstant>50.0</motorTorqueConstant>
    </actuator>
  </transmission>
  <link name="link23_rb1_arm">
    <inertial>
      <mass value="0.429"/>
      <origin xyz="0.06076 0 -0.00014"/>
      <inertia ixx="0.0011551458" ixy="-6.3e-010" ixz="2.519546e-005" iyy="0.0015754353" iyz="-7.6e-010" izz="0.0007798411"/>
    </inertial>
    <visual>
      <origin rpy="0 0 0" xyz="0 0 0"/>
      <geometry>
        <mesh filename="package://rb1_arm_description/meshes/arms/armRB1_23_link.dae"/>
      </geometry>
      <material name="darkgrey">
        <color rgba="0.1 0.1 0.1 1"/>
      </material>
    </visual>
    <collision>
      <origin rpy="0 0 0 " xyz="0 0 0"/>
      <geometry>
        <mesh filename="package://rb1_arm_description/meshes/arms/armRB1_23_link.dae"/>
      </geometry>
    </collision>
  </link>
  <link name="motor23_rb1_arm">
    <inertial>
      <mass value="0.732"/>
      <origin xyz="0.11598 0 0.00014"/>
      <!--inertia  ixx="0.01" ixy="0.0"  ixz="0.0"  iyy="0.01"  iyz="0.0"  izz="0.01" /-->
      <inertia ixx="0.02661733557" ixy="0.00029270634" ixz="0.00392189887" iyy="0.02844355207" iyz="0.0010838933" izz="0.01248008322"/>
    </inertial>
    <visual>
      <origin rpy="0 0 0" xyz="0 0 0"/>
      <geometry>
        <mesh filename="package://rb1_arm_description/meshes/arms/armRB1_23_motor.dae"/>
      </geometry>
      <material name="darkgrey">
        <color rgba="0.1 0.1 0.1 1"/>
      </material>
    </visual>
    <collision>
      <origin rpy="0 0 0 " xyz="0 0 0"/>
      <geometry>
        <mesh filename="package://rb1_arm_description/meshes/arms/armRB1_23_motor.dae"/>
      </geometry>
    </collision>
  </link>
  <joint name="j23m_rb1_arm" type="fixed">
    <origin rpy="0.0 0.0 0.0" xyz="0.0 0.0 0.0"/>
    <parent link="link23_rb1_arm"/>
    <child link="motor23_rb1_arm"/>
    <axis xyz="0 0 0"/>
  </joint>
  <joint name="j2" type="revolute">
    <origin rpy="1.57079632679 0.0 0.0" xyz="0.135 0 0"/>
    <parent link="link12_rb1_arm"/>
    <child link="link23_rb1_arm"/>
    <axis xyz="0 0 -1"/>
    <limit effort="60.0" lower="-1.570796327" upper="1.570796327" velocity="2.9217"/>
    <dynamics damping="0.7" friction="0.5"/>
  </joint>
  <transmission name="j2_trans">
    <type>transmission_interface/SimpleTransmission</type>
    <joint name="j2"/>
    <actuator name="j2_motor">
      <hardwareInterface>EffortJointInterface</hardwareInterface>
      <mechanicalReduction>502.0</mechanicalReduction>
      <motorTorqueConstant>50.0</motorTorqueConstant>
    </actuator>
  </transmission>
  <link name="link34_rb1_arm">
    <inertial>
      <mass value="0.351"/>
      <origin xyz="-0.07306 0 -0.00466"/>
      <inertia ixx="0.0003749308" ixy="0.0" ixz="-0.0001258961" iyy="0.0010047174" iyz="0.0" izz="0.0009318091"/>
    </inertial>
    <visual>
      <origin rpy="0 0 0" xyz="0 0 0"/>
      <geometry>
        <mesh filename="package://rb1_arm_description/meshes/arms/armRB1_34_link.dae"/>
      </geometry>
      <material name="darkgrey">
        <color rgba="0.1 0.1 0.1 1"/>
      </material>
    </visual>
    <collision>
      <origin rpy="0 0 0 " xyz="0 0 0"/>
      <geometry>
        <mesh filename="package://rb1_arm_description/meshes/arms/armRB1_34_link.dae"/>
      </geometry>
    </collision>
  </link>
  <link name="motor34_rb1_arm">
    <inertial>
      <mass value="0.732"/>
      <origin xyz="0.00014 0 0.00698"/>
      <inertia ixx="0.0007977173" ixy="0.0" ixz="-5.17658e-006" iyy="0.000797409" iyz="0.0" izz="0.0003233065"/>
    </inertial>
    <visual>
      <origin rpy="0 0 0" xyz="0 0 0"/>
      <geometry>
        <mesh filename="package://rb1_arm_description/meshes/arms/armRB1_34_motor.dae"/>
      </geometry>
      <material name="darkgrey">
        <color rgba="0.1 0.1 0.1 1"/>
      </material>
    </visual>
    <collision>
      <origin rpy="0 0 0 " xyz="0 0 0"/>
      <geometry>
        <mesh filename="package://rb1_arm_description/meshes/arms/armRB1_34_motor.dae"/>
      </geometry>
    </collision>
  </link>
  <joint name="j34m_rb1_arm" type="fixed">
    <origin rpy="0.0 0.0 0.0" xyz="0.0 0.0 0.0"/>
    <parent link="link34_rb1_arm"/>
    <child link="motor34_rb1_arm"/>
    <axis xyz="0 0 0"/>
  </joint>
  <joint name="j3" type="revolute">
    <origin rpy="0.0 0.0 0.0" xyz="0.310 0 0"/>
    <parent link="link23_rb1_arm"/>
    <child link="link34_rb1_arm"/>
    <axis xyz="1 0 0"/>
    <limit effort="35.0" lower="-3.13" upper="3.13" velocity="3.1527"/>
    <dynamics damping="0.7" friction="0.5"/>
  </joint>
  <transmission name="j3_trans">
    <type>transmission_interface/SimpleTransmission</type>
    <joint name="j3"/>
    <actuator name="j3_motor">
      <hardwareInterface>EffortJointInterface</hardwareInterface>
      <mechanicalReduction>502.0</mechanicalReduction>
      <motorTorqueConstant>50.0</motorTorqueConstant>
    </actuator>
  </transmission>
  <link name="link45_rb1_arm">
    <inertial>
      <mass value="0.388"/>
      <origin xyz="0.05882 0 -0.00029"/>
      <inertia ixx="0.0008598409" ixy="-6.1e-010" ixz="2.148066e-005" iyy="0.00127317" iyz="-6.6e-010" izz="0.0007358862"/>
    </inertial>
    <visual>
      <origin rpy="0 0 0" xyz="0 0 0"/>
      <geometry>
        <mesh filename="package://rb1_arm_description/meshes/arms/armRB1_45_link.dae"/>
      </geometry>
      <material name="darkgrey">
        <color rgba="0.1 0.1 0.1 1"/>
      </material>
    </visual>
    <collision>
      <origin rpy="0 0 0 " xyz="0 0 0"/>
      <geometry>
        <mesh filename="package://rb1_arm_description/meshes/arms/armRB1_45_link.dae"/>
      </geometry>
    </collision>
  </link>
  <link name="motor45_rb1_arm">
    <inertial>
      <mass value="0.732"/>
      <origin xyz="0.11398 0 0.00014"/>
      <inertia ixx="0.0003233065" ixy="0.0" ixz="-5.17658e-006" iyy="0.000797409" iyz="0.0" izz="0.0007977173"/>
    </inertial>
    <visual>
      <origin rpy="0 0 0" xyz="0 0 0"/>
      <geometry>
        <mesh filename="package://rb1_arm_description/meshes/arms/armRB1_45_motor.dae"/>
      </geometry>
      <material name="darkgrey">
        <color rgba="0.1 0.1 0.1 1"/>
      </material>
    </visual>
    <collision>
      <origin rpy="0 0 0 " xyz="0 0 0"/>
      <geometry>
        <mesh filename="package://rb1_arm_description/meshes/arms/armRB1_45_motor.dae"/>
      </geometry>
    </collision>
  </link>
  <joint name="j45m_rb1_arm" type="fixed">
    <origin rpy="0.0 0.0 0.0" xyz="0.0 0.0 0.0"/>
    <parent link="link45_rb1_arm"/>
    <child link="motor45_rb1_arm"/>
    <axis xyz="0 0 0"/>
  </joint>
  <joint name="j4" type="revolute">
    <origin rpy="0.0 0.0 0.0" xyz="0 0 0"/>
    <parent link="link34_rb1_arm"/>
    <child link="link45_rb1_arm"/>
    <axis xyz="0 0 -1"/>
    <limit effort="35.0" lower="-1.570796327" upper="1.570796327" velocity="3.1527"/>
    <dynamics damping="0.7" friction="0.5"/>
  </joint>
  <transmission name="j4_trans">
    <type>transmission_interface/SimpleTransmission</type>
    <joint name="j4"/>
    <actuator name="j4_motor">
      <hardwareInterface>EffortJointInterface</hardwareInterface>
      <mechanicalReduction>502.0</mechanicalReduction>
      <motorTorqueConstant>5.0</motorTorqueConstant>
    </actuator>
  </transmission>
  <link name="link56_rb1_arm">
    <inertial>
      <mass value="0.3559"/>
      <origin xyz="-0.05587 0 0.0189"/>
      <inertia ixx="0.0006065534" ixy="-3.8893e-007" ixz="8.365509e-005" iyy="0.0012291083" iyz="-2.9944e-007" izz="0.000821452"/>
    </inertial>
    <visual>
      <origin rpy="0 0 0" xyz="0 0 0"/>
      <geometry>
        <mesh filename="package://rb1_arm_description/meshes/arms/armRB1_56_link.dae"/>
      </geometry>
      <material name="darkgrey">
        <color rgba="0.1 0.1 0.1 1"/>
      </material>
    </visual>
    <collision>
      <origin rpy="0 0 0 " xyz="0 0 0"/>
      <geometry>
        <mesh filename="package://rb1_arm_description/meshes/arms/armRB1_56_link.dae"/>
      </geometry>
    </collision>
  </link>
  <link name="motor56_rb1_arm">
    <inertial>
      <mass value="0.34"/>
      <origin xyz="0 0 0"/>
      <inertia ixx="0.0002196171" ixy="0.0" ixz="2.3781e-006" iyy="0.0002200183" iyz="0.0" izz="9.300873e-005"/>
    </inertial>
    <visual>
      <origin rpy="0 0 0" xyz="0 0 0"/>
      <geometry>
        <mesh filename="package://rb1_arm_description/meshes/arms/armRB1_56_motor.dae"/>
      </geometry>
      <material name="darkgrey">
        <color rgba="0.1 0.1 0.1 1"/>
      </material>
    </visual>
    <collision>
      <origin rpy="0 0 0 " xyz="0 0 0"/>
      <geometry>
        <mesh filename="package://rb1_arm_description/meshes/arms/armRB1_56_motor.dae"/>
      </geometry>
    </collision>
  </link>
  <joint name="j56m_rb1_arm" type="fixed">
    <origin rpy="0.0 0.0 0.0" xyz="0.0 0.0 0.0"/>
    <parent link="link56_rb1_arm"/>
    <child link="motor56_rb1_arm"/>
    <axis xyz="0 0 0"/>
  </joint>
  <joint name="j5" type="revolute">
    <origin rpy="0.0 0.0 0.0" xyz="0.285 0 0"/>
    <parent link="link45_rb1_arm"/>
    <child link="link56_rb1_arm"/>
    <axis xyz="1 0 0"/>
    <limit effort="35.0" lower="-3.13" upper="3.13" velocity="3.1527"/>
    <dynamics damping="0.7" friction="0.5"/>
  </joint>
  <transmission name="j5_trans">
    <type>transmission_interface/SimpleTransmission</type>
    <joint name="j5"/>
    <actuator name="j5_motor">
      <hardwareInterface>EffortJointInterface</hardwareInterface>
      <mechanicalReduction>502.0</mechanicalReduction>
      <motorTorqueConstant>5.0</motorTorqueConstant>
    </actuator>
  </transmission>
  <link name="link67_rb1_arm">
    <inertial>
      <mass value="0.055"/>
      <origin xyz="-0.00099 0 0.0035"/>
      <inertia ixx="4.888031e-005" ixy="0.0" ixz="1.5733e-007" iyy="4.899477e-005" iyz="0.0" izz="9.65717e-006"/>
    </inertial>
    <visual>
      <origin rpy="0 0 0" xyz="0 0 0"/>
      <geometry>
        <mesh filename="package://rb1_arm_description/meshes/arms/armRB1_67_link.dae"/>
      </geometry>
      <material name="darkgrey">
        <color rgba="0.1 0.1 0.1 1"/>
      </material>
    </visual>
    <collision>
      <origin rpy="0 0 0 " xyz="0 0 0"/>
      <geometry>
        <mesh filename="package://rb1_arm_description/meshes/arms/armRB1_67_link.dae"/>
      </geometry>
    </collision>
  </link>
  <link name="motor67_rb1_arm">
    <inertial>
      <mass value="0.34"/>
      <origin xyz="-0.01895 -0.00019 0"/>
      <inertia ixx="9.300873e-005" ixy="2.3781e-006" ixz="0.0" iyy="0.0002196171" iyz="0.0" izz="0.0002200183"/>
    </inertial>
    <visual>
      <origin rpy="0 0 0" xyz="0 0 0"/>
      <geometry>
        <mesh filename="package://rb1_arm_description/meshes/arms/armRB1_67_motor.dae"/>
      </geometry>
      <material name="darkgrey">
        <color rgba="0.1 0.1 0.1 1"/>
      </material>
    </visual>
    <collision>
      <origin rpy="0 0 0 " xyz="0 0 0"/>
      <geometry>
        <mesh filename="package://rb1_arm_description/meshes/arms/armRB1_67_motor.dae"/>
      </geometry>
    </collision>
  </link>
  <joint name="j67m_rb1_arm" type="fixed">
    <origin rpy="0.0 0.0 0.0" xyz="0.0 0.0 0.0"/>
    <parent link="link67_rb1_arm"/>
    <child link="motor67_rb1_arm"/>
    <axis xyz="0 0 0"/>
  </joint>
  <joint name="j6" type="revolute">
    <origin rpy="0.0 0.0 0.0" xyz="0 0 0"/>
    <parent link="link56_rb1_arm"/>
    <child link="link67_rb1_arm"/>
    <axis xyz="0 0 -1"/>
    <limit effort="8.0" lower="-1.570796327" upper="1.570796327" velocity="2.98452"/>
    <dynamics damping="0.7" friction="0.5"/>
  </joint>
  <transmission name="j6_trans">
    <type>transmission_interface/SimpleTransmission</type>
    <joint name="j6"/>
    <actuator name="j6_motor">
      <hardwareInterface>EffortJointInterface</hardwareInterface>
      <mechanicalReduction>304.0</mechanicalReduction>
      <motorTorqueConstant>3.0</motorTorqueConstant>
    </actuator>
  </transmission>
  <link name="end_effector_rb1_arm">
	    
    </link>
  <joint name="j7" type="revolute">
    <origin rpy="0.0 0.0 0.0" xyz="0 0 0"/>
    <parent link="link67_rb1_arm"/>
    <child link="end_effector_rb1_arm"/>
    <axis xyz="0 0 -1"/>
    <limit effort="8.0" lower="-3.13" upper="3.13" velocity="2.98452"/>
    <dynamics damping="0.7" friction="0.5"/>
  </joint>
  <transmission name="j7_trans">
    <type>transmission_interface/SimpleTransmission</type>
    <joint name="j7"/>
    <actuator name="j7_motor">
      <hardwareInterface>EffortJointInterface</hardwareInterface>
      <mechanicalReduction>304.0</mechanicalReduction>
      <motorTorqueConstant>3.0</motorTorqueConstant>
    </actuator>
  </transmission>
  <!-- Gazebo ros control plugins -->
  <gazebo>
    <plugin filename="libgazebo_ros_control.so" name="ros_control">
      <robotNamespace>/rb1</robotNamespace>
      <robotParam>robot_description</robotParam>
      <controlPeriod>0.001</controlPeriod>
      <robotSimType>gazebo_ros_control/DefaultRobotHWSim</robotSimType>
    </plugin>
  </gazebo>
</robot>

