<?xml version="1.0"?>
<robot name="rb1_torso_3dof" xmlns:xacro="http://www.ros.org/wiki/xacro"> 

  <xacro:property name="joint_effort_limit" value="100.0"/>
  <xacro:property name="joint_velocity_limit" value="3.0"/>
  <xacro:property name="joint_effort_limit_torso" value="5000.0"/>
  <xacro:property name="joint_velocity_limit_torso" value="1.0"/>
  <xacro:property name="joint_damping" value="0.5"/>
  <xacro:property name="joint_friction" value="0.5"/>

  <xacro:property name="torso_slider_joint_mechanical_reduction" value="320.0"/>
  <xacro:property name="torso_slider_joint_motor_torque_constant" value="1.0"/>
  <xacro:property name="head_pan_joint_mechanical_reduction" value="320.0"/>
  <xacro:property name="head_pan_joint_motor_torque_constant" value="1.0"/>
  <xacro:property name="head_tilt_joint_mechanical_reduction" value="320.0"/>
  <xacro:property name="head_tilt_joint_motor_torque_constant" value="1.0"/>

  <xacro:macro name="rb1_torso_3dof" params="base_parent hq">

    <!-- Robot mechanical and motor parameters -->
    <xacro:property name="PI" value="3.1415926535897931"/>
    
    <link name="torso_link">
      <inertial>
        <mass value="3.0" />
        <origin xyz="0 0 0" />
        <inertia  ixx="1.0" ixy="0.0"  ixz="0.0"  iyy="1.0"  iyz="0.0"  izz="1.0" />
      </inertial>
      <visual>
        <origin xyz="0 0 0" rpy="0 0 0" />
        <xacro:if value="${hq}">
        <geometry>
        <mesh filename="package://rb1_torso_description/meshes/torsos/rb1v2_superior1.dae"/>
        </geometry>
        </xacro:if>
        <xacro:unless value="${hq}">
        <geometry>
        <mesh filename="package://rb1_torso_description/meshes/torsos/rb1v2_superior1.dae"/>
        </geometry>
        </xacro:unless>
        <material name="darkgrey">
          <color rgba="0.1 0.1 0.1 1"/>
        </material>
      </visual>  
      <collision>
        <origin xyz="0 0 0" rpy="0 0 0 " />
        <geometry>
          <mesh filename="package://rb1_torso_description/meshes/torsos/rb1v2_superior1.dae"/>
        </geometry>
      </collision>
    </link>

    <joint name="torso_joint" type="fixed">
      <origin xyz="0.0 0.0 0.0" rpy="0.0 0.0 0.0" />
      <parent link="${base_parent}" />
      <child link="torso_link" />
      <axis xyz="0 0 0" />
    </joint>

    <link name="torso_guide_link">
      <inertial>
        <mass value="2.0" />
        <origin xyz="0 0 0" />
        <inertia  ixx="1.0" ixy="0.0"  ixz="0.0"  iyy="1.0"  iyz="0.0"  izz="1.0" />
      </inertial>
      <visual>
        <origin xyz="0 0 0" rpy="0 0 0" />
        <xacro:if value="${hq}">
        <geometry>
        <mesh filename="package://rb1_torso_description/meshes/torsos/rb1v2_guide.dae"/>
        </geometry>
        </xacro:if>
        <xacro:unless value="${hq}">
        <geometry>
        <mesh filename="package://rb1_torso_description/meshes/torsos/rb1v2_guide.dae"/>
        </geometry>
        </xacro:unless>
        <material name="darkgrey">
          <color rgba="0.1 0.1 0.1 1"/>
        </material>
      </visual>  
      <collision>
        <origin xyz="0 0 0" rpy="0 0 0 " />
        <geometry>
          <mesh filename="package://rb1_torso_description/meshes/torsos/rb1v2_guide.dae"/>
        </geometry>
      </collision>
    </link>

    <joint
      name="torso_guide_joint"
        type="fixed">
      <origin
        xyz="0.0 0.0 0.0"
        rpy="0.0 0.0 0.0" />
      <parent
        link="torso_link" />
      <child
        link="torso_guide_link" />
      <axis
        xyz="0 0 0" />
    </joint>


    <link name="torso_slider_link">
      <inertial>
        <mass value="2.0" />
        <origin xyz="0 0 0" />
        <inertia  ixx="1.0" ixy="0.0"  ixz="0.0"  iyy="1.0"  iyz="0.0"  izz="1.0" />
      </inertial>
      <visual>
        <origin xyz="0 0 0" rpy="0 0 0" />
        <xacro:if value="${hq}">
        <geometry>
        <mesh filename="package://rb1_torso_description/meshes/torsos/rb1v2_superior2.dae"/>
        </geometry>
        </xacro:if>
        <xacro:unless value="${hq}">
        <geometry>
        <mesh filename="package://rb1_torso_description/meshes/torsos/rb1v2_superior2.dae"/>
        </geometry>
        </xacro:unless>
        <material name="darkgrey">
          <color rgba="0.1 0.1 0.1 1"/>
        </material>
      </visual>  
      <collision>
        <origin xyz="0 0 0" rpy="0 0 0 " />
        <geometry>
          <mesh filename="package://rb1_torso_description/meshes/torsos/rb1v2_superior2.dae"/>
        </geometry>
      </collision>
    </link>

    <joint name="torso_slider_joint" type="prismatic">
      <origin xyz="0.07 0 0.091" rpy="0.0 0.0 0.0" />
      <parent link="torso_link" />	
      <child link="torso_slider_link" />
      <axis xyz="0 0 1" />
      <limit effort="${joint_effort_limit_torso}" velocity="${joint_velocity_limit_torso}" upper="${0.3645}" lower="${0}"/>
      <dynamics damping="${joint_damping}" friction="${joint_friction}"/>
    </joint>

    <transmission name="torso_slider_trans">
      <type>transmission_interface/SimpleTransmission</type>
      <joint name="torso_slider_joint">
        <hardwareInterface>hardware_interface/EffortJointInterface</hardwareInterface>
      </joint>
      
      <actuator name="torso_slider_motor"> 
        <hardwareInterface>hardware_interface/EffortJointInterface</hardwareInterface>
        <mechanicalReduction>${torso_slider_joint_mechanical_reduction}</mechanicalReduction>
        <motorTorqueConstant>${torso_slider_joint_motor_torque_constant}</motorTorqueConstant>
      </actuator>	 
    </transmission>

    <!--joint
      name="torso_slider_joint"
        type="fixed">
      <origin
        xyz="0.07 0 0.091"
        rpy="0.0 0.0 0.0" />
      <parent
        link="torso_link" />
      <child
        link="torso_slider_link" />
      <axis
        xyz="0 0 0" />
    </joint-->

    <link name="torso_cover_link">
      <inertial>
        <mass value="1.0" />
        <origin xyz="0 0 0" />
        <inertia  ixx="1.0" ixy="0.0"  ixz="0.0"  iyy="1.0"  iyz="0.0"  izz="1.0" />
      </inertial>
      <visual>
        <origin xyz="0 0 0" rpy="0 0 0" />
        <xacro:if value="${hq}">
        <geometry>
        <mesh filename="package://rb1_torso_description/meshes/torsos/rb1v2_rear_cover.dae"/>
        </geometry>
        </xacro:if>
        <xacro:unless value="${hq}">
        <geometry>
        <mesh filename="package://rb1_torso_description/meshes/torsos/rb1v2_rear_cover.dae"/>
        </geometry>
        </xacro:unless>
        <material name="darkgrey">
          <color rgba="0.1 0.1 0.1 1"/>
        </material>
      </visual>  
      <collision>
        <origin xyz="0 0 0" rpy="0 0 0 " />
        <geometry>
          <mesh filename="package://rb1_torso_description/meshes/torsos/rb1v2_rear_cover.dae"/>
        </geometry>
      </collision>
    </link>

    <joint name="torso_cover_joint" type="fixed">
      <origin xyz="-0.164 0.0 0.0" rpy="0.0 0.0 0.0" />
      <parent link="torso_slider_link" />
      <child link="torso_cover_link" />
      <axis xyz="0 0 0" />
    </joint>


    <link name="head_link">
      <inertial>
        <mass value="1.0" />
        <origin xyz="0 0 0" />
        <inertia  ixx="1.0" ixy="0.0"  ixz="0.0"  iyy="1.0"  iyz="0.0"  izz="1.0" />
      </inertial>
      <visual>
        <origin xyz="0 0 0" rpy="0 0 0" />
        <xacro:if value="${hq}">
        <geometry>
        <mesh filename="package://rb1_torso_description/meshes/heads/rb1v2_head1.dae"/>
        </geometry>
        </xacro:if>
        <xacro:unless value="${hq}">
        <geometry>
        <mesh filename="package://rb1_torso_description/meshes/heads/rb1v2_head1.dae"/>
        </geometry>
        </xacro:unless>
        <material name="darkgrey">
          <color rgba="0.1 0.1 0.1 1"/>
        </material>
      </visual>  
      <collision>
        <origin xyz="0 0 0" rpy="0 0 0 " />
        <geometry>
          <mesh filename="package://rb1_torso_description/meshes/heads/rb1v2_head1.dae"/>
        </geometry>
      </collision>
    </link>

    <joint name="head_pan_joint" type="revolute">
      <origin xyz="0.055 0.0 0.621" rpy="0.0 0.0 0.0" />
      <parent link="torso_slider_link" />	
      <child link="head_link" />
      <axis xyz="0 0 1" />
      <limit effort="${joint_effort_limit}" velocity="${joint_velocity_limit}" upper="${PI/2}" lower="${-PI/2}"/>
      <dynamics damping="${joint_damping}" friction="${joint_friction}"/>
    </joint>

    <transmission name="head_pan_trans">
      <type>transmission_interface/SimpleTransmission</type>
        <joint name="head_pan_joint">
            <hardwareInterface>hardware_interface/EffortJointInterface</hardwareInterface>
        </joint>

        <actuator name="head_pan_motor">
          <hardwareInterface>hardware_interface/EffortJointInterface</hardwareInterface>
          <mechanicalReduction>${head_pan_joint_mechanical_reduction}</mechanicalReduction>
          <motorTorqueConstant>${head_pan_joint_motor_torque_constant}</motorTorqueConstant>
      </actuator>	 
    </transmission>

    <!--joint
      name="head_pan_joint"
        type="fixed">
      <origin
        xyz="0.055 0.0 0.621"
        rpy="0.0 0.0 0.0" />
      <parent
        link="torso_slider_link" />
      <child
        link="head_link" />
      <axis
        xyz="0 0 0" />
    </joint-->


    <link name="head_tilt_link">
      <inertial>
        <mass value="1.0" />
        <origin xyz="0 0 0" />
        <inertia  ixx="1.0" ixy="0.0"  ixz="0.0"  iyy="1.0"  iyz="0.0"  izz="1.0" />
      </inertial>
      <visual>
        <origin xyz="0 0 0" rpy="0 0 0" />
        <xacro:if value="${hq}">
        <geometry>
        <mesh filename="package://rb1_torso_description/meshes/heads/rb1v2_head2.dae"/>
        </geometry>
        </xacro:if>
        <xacro:unless value="${hq}">
        <geometry>
        <mesh filename="package://rb1_torso_description/meshes/heads/rb1v2_head2.dae"/>
        </geometry>
        </xacro:unless>
        <material name="darkgrey">
          <color rgba="0.1 0.1 0.1 1"/>
        </material>
      </visual>  
      <collision>
        <origin xyz="0 0 0" rpy="0 0 0 " />
        <geometry>
          <mesh filename="package://rb1_torso_description/meshes/heads/rb1v2_head2.dae"/>
        </geometry>
      </collision>
    </link>


    <joint name="head_tilt_joint" type="revolute">
      <origin xyz="0.081 0.0 0.0" rpy="0.0 0.0 0.0" />
      <parent link="head_link" />	
      <child link="head_tilt_link" />
      <axis xyz="0 1 0"/>
      <limit effort="${joint_effort_limit}" velocity="${joint_velocity_limit}" upper="${PI/4}" lower="${-PI/4}"/>
      <dynamics damping="${joint_damping}" friction="${joint_friction}"/>
    </joint>

    <transmission name="head_tilt_trans">
      <type>transmission_interface/SimpleTransmission</type>
        <joint name="head_tilt_joint">
          <hardwareInterface>hardware_interface/EffortJointInterface</hardwareInterface>
        </joint>

        <actuator name="head_tilt_motor">	 
        <hardwareInterface>hardware_interface/EffortJointInterface</hardwareInterface>
        <mechanicalReduction>${head_tilt_joint_mechanical_reduction}</mechanicalReduction>
        <motorTorqueConstant>${head_tilt_joint_motor_torque_constant}</motorTorqueConstant>
      </actuator>	 
    </transmission>

    <!--joint
      name="head_tilt_joint"
        type="fixed">
      <origin
        xyz="0.081 0.0 0.0"
        rpy="0.0 0.0 0.0" />
      <parent
        link="head_link" />
      <child
        link="head_tilt_link" />
      <axis
        xyz="0 0 0" />
    </joint-->

  </xacro:macro>
</robot>

