<?xml version="1.0"?>
<robot name="rb1_torso_3dof" xmlns:xacro="http://www.ros.org/wiki/xacro"> 

  <!-- xacro:include filename="$(find rb1_torso_description)/urdf/rb1_torso_3dof.gazebo.xacro" / -->

  <xacro:property name="joint_effort_limit" value="100.0"/>
  <xacro:property name="joint_velocity_limit" value="3.0"/>
  <xacro:property name="joint_effort_limit_torso" value="5000.0"/>
  <xacro:property name="joint_velocity_limit_torso" value="1.0"/>
  <xacro:property name="joint_damping" value="0.5"/>
  <xacro:property name="joint_friction" value="0.5"/>

  <xacro:property name="torso_slider_joint_mechanical_reduction" value="320.0"/>
  <xacro:property name="torso_slider_joint_motor_torque_constant" value="1.0"/>
  <xacro:property name="head_pan_joint_mechanical_reduction" value="320.0"/>
  <xacro:property name="head_pan_joint_motor_torque_constant" value="1.0"/>
  <xacro:property name="head_tilt_joint_mechanical_reduction" value="320.0"/>
  <xacro:property name="head_tilt_joint_motor_torque_constant" value="1.0"/>

  <xacro:macro name="rb1_torso_3dof" params="name hq">

  <!-- Robot mechanical and motor parameters -->
  <xacro:property name="PI" value="3.1415926535897931"/>
 
  <!-- BASE_LINK -->
  <link
    name="torso_base_link">
  </link>
  
  <joint
	  name="torso_joint"
      type="fixed">
    <origin
      xyz="0.0 0.0 0.0"
      rpy="0.0 0.0 0.0" />
    <parent
      link="torso_base_link" />
    <child
      link="torso_link" />
    <axis
      xyz="0 0 0" />
  </joint>		
  
  <link name="torso_link">
    <inertial>
      <mass value="3.0" />
      <origin xyz="0 0 0" />
      <inertia  ixx="1.0" ixy="0.0"  ixz="0.0"  iyy="1.0"  iyz="0.0"  izz="1.0" />
    </inertial>
    <visual>
       <origin xyz="0 0 0" rpy="0 0 0" />
       <xacro:if value="${hq}">
       <geometry>
	     <mesh filename="package://rb1_torso_description/meshes/torsos/rb1_torso_lower_v3.stl"/>
       </geometry>
       </xacro:if>
       <xacro:unless value="${hq}">
       <geometry>
       <mesh filename="package://rb1_torso_description/meshes/torsos/rb1_torso_lower_v3.stl"/>
       </geometry>
       </xacro:unless>
       <material name="darkgrey">
         <color rgba="0.1 0.1 0.1 1"/>
       </material>
    </visual>  
    <collision>
       <origin xyz="0 0 0" rpy="0 0 0 " />
       <geometry>
         <mesh filename="package://rb1_torso_description/meshes/torsos/rb1_torso_lower_v3.stl"/>
       </geometry>
    </collision>
  </link>

  <joint name="torso_slider_joint"
	type="prismatic">
	<origin
      xyz="0.0 0 0.105" 
      rpy="0.0 0.0 0.0" />
	<parent link="torso_link" />	
    <child link="torso_slider_link" />
    <axis xyz="0 0 1" />
    <limit effort="${joint_effort_limit_torso}" velocity="${joint_velocity_limit_torso}" upper="${0.350}" lower="${0}"/>
    <dynamics damping="${joint_damping}" friction="${joint_friction}"/>
  </joint>

  <transmission name="torso_slider_trans">
	 <type>transmission_interface/SimpleTransmission</type>
     <joint name="torso_slider_joint">
		 <hardwareInterface>EffortJointInterface</hardwareInterface>
     </joint>
     <actuator name="torso_slider_motor">	    
        <mechanicalReduction>${torso_slider_joint_mechanical_reduction}</mechanicalReduction>
		<motorTorqueConstant>${torso_slider_joint_motor_torque_constant}</motorTorqueConstant>
	 </actuator>	 
  </transmission>


  <link name="torso_slider_link">
    <inertial>
      <mass value="2.0" />
      <origin xyz="0 0 0" />
      <inertia  ixx="1.0" ixy="0.0"  ixz="0.0"  iyy="1.0"  iyz="0.0"  izz="1.0" />
    </inertial>
    <visual>
       <origin xyz="0 0 0" rpy="0 0 0" />
       <xacro:if value="${hq}">
       <geometry>
	     <mesh filename="package://rb1_torso_description/meshes/torsos/rb1_torso_upper_v3.stl"/>
       </geometry>
       </xacro:if>
       <xacro:unless value="${hq}">
       <geometry>
       <mesh filename="package://rb1_torso_description/meshes/torsos/rb1_torso_upper_v3.stl"/>
       </geometry>
       </xacro:unless>
       <material name="darkgrey">
         <color rgba="0.1 0.1 0.1 1"/>
       </material>
    </visual>  
    <collision>
       <origin xyz="0 0 0" rpy="0 0 0 " />
       <geometry>
         <mesh filename="package://rb1_torso_description/meshes/torsos/rb1_torso_upper_v3.stl"/>
       </geometry>
    </collision>
  </link>

   <joint
	  name="torso_cover_joint"
      type="fixed">
    <origin
      xyz="0.0 0.0 0.0"
      rpy="0.0 0.0 0.0" />
    <parent
      link="torso_link" />
    <child
      link="torso_cover_link" />
    <axis
      xyz="0 0 0" />
  </joint>


  <link name="torso_cover_link">
    <inertial>
      <mass value="1.0" />
      <origin xyz="0 0 0" />
      <inertia  ixx="1.0" ixy="0.0"  ixz="0.0"  iyy="1.0"  iyz="0.0"  izz="1.0" />
    </inertial>
    <visual>
       <origin xyz="0 0 0" rpy="0 0 0" />
       <xacro:if value="${hq}">
       <geometry>
	     <mesh filename="package://rb1_torso_description/meshes/torsos/rb1_torso_cover_v3.stl"/>
       </geometry>
       </xacro:if>
       <xacro:unless value="${hq}">
       <geometry>
       <mesh filename="package://rb1_torso_description/meshes/torsos/rb1_torso_cover_v3.stl"/>
       </geometry>
       </xacro:unless>
       <material name="darkgrey">
         <color rgba="0.1 0.1 0.1 1"/>
       </material>
    </visual>  
    <collision>
       <origin xyz="0 0 0" rpy="0 0 0 " />
       <geometry>
         <mesh filename="package://rb1_torso_description/meshes/torsos/rb1_torso_cover_v3.stl"/>
       </geometry>
    </collision>
  </link>
  
    <joint
	name="head_pan_joint"
	type="revolute">
	<origin
      xyz="0.0 0.0 0.521"
      rpy="0.0 0.0 0.0" />
	<parent link="torso_slider_link" />	
    <child link="head_link" />
    <axis xyz="0 0 1" />
    <limit effort="${joint_effort_limit}" velocity="${joint_velocity_limit}" upper="${PI/2}" lower="${-PI/2}"/>
    <dynamics damping="${joint_damping}" friction="${joint_friction}"/>
  </joint>

  <transmission name="head_pan_trans">
	 <type>transmission_interface/SimpleTransmission</type>
     <joint name="head_pan_joint">
        <hardwareInterface>EffortJointInterface</hardwareInterface>
     </joint>     
     <actuator name="head_pan_motor">
        <mechanicalReduction>${head_pan_joint_mechanical_reduction}</mechanicalReduction>
		<motorTorqueConstant>${head_pan_joint_motor_torque_constant}</motorTorqueConstant>
	 </actuator>	 
  </transmission>



  <link name="head_link">
    <inertial>
      <mass value="1.0" />
      <origin xyz="0 0 0" />
      <inertia  ixx="1.0" ixy="0.0"  ixz="0.0"  iyy="1.0"  iyz="0.0"  izz="1.0" />
    </inertial>
    <visual>
       <origin xyz="0 0 0" rpy="0 0 0" />
       <xacro:if value="${hq}">
       <geometry>
	     <mesh filename="package://rb1_torso_description/meshes/heads/rb1v2_head1.dae"/>
       </geometry>
       </xacro:if>
       <xacro:unless value="${hq}">
       <geometry>
       <mesh filename="package://rb1_torso_description/meshes/heads/rb1v2_head1.stl"/>
       </geometry>
       </xacro:unless>
       <material name="darkgrey">
         <color rgba="0.1 0.1 0.1 1"/>
       </material>
    </visual>  
    <collision>
       <origin xyz="0 0 0" rpy="0 0 0 " />
       <geometry>
         <mesh filename="package://rb1_torso_description/meshes/heads/rb1v2_head1.dae"/>
       </geometry>
    </collision>
  </link>

  <joint
	name="head_tilt_joint"
	type="revolute">
	<origin
      xyz="0.081 0.0 0.0"
      rpy="0.0 0.0 0.0" />
	<parent link="head_link" />	
    <child link="head_tilt_link" />
    <!-- check -->
    <!-- axis xyz="0 1 0" / -->
    <axis xyz="0 -1 0"/>
    <limit effort="${joint_effort_limit}" velocity="${joint_velocity_limit}" upper="${PI/2}" lower="${-PI/2}"/>
    <dynamics damping="${joint_damping}" friction="${joint_friction}"/>
  </joint>

  <transmission name="head_tilt_trans">
	 <type>transmission_interface/SimpleTransmission</type>
     <joint name="head_tilt_joint">
		<hardwareInterface>EffortJointInterface</hardwareInterface>
	 </joint>
     <actuator name="head_tilt_motor">	 
        <mechanicalReduction>${head_tilt_joint_mechanical_reduction}</mechanicalReduction>
		<motorTorqueConstant>${head_tilt_joint_motor_torque_constant}</motorTorqueConstant>
	 </actuator>	 
  </transmission>



  <link name="head_tilt_link">
    <inertial>
      <mass value="1.0" />
      <origin xyz="0 0 0" />
      <inertia  ixx="1.0" ixy="0.0"  ixz="0.0"  iyy="1.0"  iyz="0.0"  izz="1.0" />
    </inertial>
    <visual>
       <origin xyz="0 0 0" rpy="0 0 0" />
       <xacro:if value="${hq}">
       <geometry>
	     <mesh filename="package://rb1_torso_description/meshes/heads/rb1v2_head2.dae"/>
       </geometry>
       </xacro:if>
       <xacro:unless value="${hq}">
       <geometry>
       <mesh filename="package://rb1_torso_description/meshes/heads/rb1v2_head2.stl"/>
       </geometry>
       </xacro:unless>
       <material name="darkgrey">
         <color rgba="0.1 0.1 0.1 1"/>
       </material>
    </visual>  
    <collision>
       <origin xyz="0 0 0" rpy="0 0 0 " />
       <geometry>
         <mesh filename="package://rb1_torso_description/meshes/heads/rb1v2_head2.dae"/>
       </geometry>
    </collision>
  </link>



  </xacro:macro>
</robot>

