<?xml version="1.0" ?>
<!-- =================================================================================== -->
<!-- |    This document was autogenerated by xacro from rb1_robot.urdf.xacro           | -->
<!-- |    EDITING THIS FILE BY HAND IS NOT RECOMMENDED                                 | -->
<!-- =================================================================================== -->
<robot name="rb1" xmlns:xacro="http://www.ros.org/wiki/xacro">
  <!-- ***************** -->
  <!-- Imported elements -->
  <!-- ***************** -->
  <!-- First we import all posible elements defined in the urdf.xacro files. All these elements are defined as macro:xacros -->
  <!-- Import RB1 base -->
  <!-- ***************** -->
  <!-- Imported elements -->
  <!-- ***************** -->
  <!-- First we import all posible elements defined in the urdf.xacro files. All these elements are defined as macro:xacros -->
  <!-- Import RB1 base elements -->
  <!-- ros control plugin -->
  <!-- xacro:macro name="ros_control">
    <gazebo>
      <plugin name="ros_control" filename="libgazebo_ros_control.so">		
        <robotNamespace>/rb1</robotNamespace>
        <robotParam>robot_description</robotParam>
        <controlPeriod>0.001</controlPeriod> 
	    <robotSimType>gazebo_ros_control/DefaultRobotHWSim</robotSimType>
      </plugin>
    </gazebo>
	</xacro:macro -->
  <!-- differential drive plugin -->
  <gazebo reference="base_footprint">
    <material>Gazebo/Green</material>
  </gazebo>
  <!-- Import RB1 wheels -->
  <!-- Wheels -->
  <!-- in kg-->
  <!-- Wheels -->
  <!-- in kg-->
  <!-- Import all available sensors -->
  <!-- This file unifies all sensors that can be used on simulation, defined as xacro:macros -->
  <!-- Axis p5512 -->
  <!-- Axis m5013 -->
  <!-- Fotonic -->
  <!-- GPS -->
  <!-- Hokuyo urg04lx -->
  <!-- Hokuyo utm30lx -->
  <!-- Hokuyo ust10lx -->
  <!-- Imu -->
  <!-- Kinect -->
  <!-- Asus Xtion PRO -->
  <!-- Xacro properties -->
  <!-- Hokuyo 3d -->
  <!-- KinectV2 -->
  <!-- ***************** -->
  <!-- Global parameters -->
  <!-- ***************** -->
  <!-- Wheel parameters -->
  <!-- x,y,z in translation from base_link to the center of the wheel -->
  <!-- Castor paramters -->
  <!-- Flag to select the high or low quality model -->
  <!-- *************** -->
  <!-- Robots Elements -->
  <!-- *************** -->
  <!-- Here we create the robot elements using the xacro:macros imported at the beggining of this file -->
  <!-- RB-1 base -->
  <!-- Robot mechanical and motor parameters -->
  <xacro:property name="PI" value="3.1415926535897931"/>
  <xacro:property name="wheel_width" value="0.175"/>
  <!-- BASE FOOTPRINT -->
  <link name="base_footprint">
    <visual>
      <origin rpy="0 0 0" xyz="0 0 0"/>
      <geometry>
        <box size="0.001 0.001 0.001"/>
      </geometry>
    </visual>
  </link>
  <joint name="base_footprint_joint" type="fixed">
    <origin rpy="0 0 0" xyz="0 0 0.025"/>
    <parent link="base_footprint"/>
    <child link="base_link"/>
  </joint>
  <!-- BASE_LINK -->
  <link name="base_link">
    <inertial>
      <mass value="25.0"/>
      <origin xyz="0 0 0"/>
      <inertia ixx="0.007" ixy="0.0" ixz="0.0" iyy="0.007" iyz="0.0" izz="0.78"/>
    </inertial>
    <visual>
      <origin rpy="0 0 0" xyz="0 0 0"/>
      <geometry>
        <mesh filename="package://rb1_base_description/meshes/bases/rb1_base.dae"/>
      </geometry>
      <material name="darkgrey">
        <color rgba="0.1 0.1 0.1 1"/>
      </material>
    </visual>
    <collision>
      <origin rpy="0 0 0 " xyz="0 0 0"/>
      <geometry>
        <mesh filename="package://rb1_base_description/meshes/bases/rb1_base.dae"/>
      </geometry>
    </collision>
  </link>
  <!-- Gazebo ros control plugins -->
  <xacro:ros_control/>
  <!-- Gazebo skid steering plugins -->
  <gazebo>
    <plugin filename="libgazebo_ros_diff_drive.so" name="differential_drive_controller">
      <alwaysOn>true</alwaysOn>
      <updateRate>50.0</updateRate>
      <!-- leftJoint>joint_left_wheel</leftJoint>
        <rightJoint>joint_right_wheel</rightJoint -->
      <leftJoint>joint_right_wheel</leftJoint>
      <rightJoint>joint_left_wheel</rightJoint>
      <!-- For V0 0.365 -->
      <!-- wheelSeparation>0.365</wheelSeparation -->
      <wheelSeparation>0.433</wheelSeparation>
      <wheelDiameter>0.1524</wheelDiameter>
      <commandTopic>/rb1/cmd_vel</commandTopic>
      <odometryTopic>odom</odometryTopic>
      <odometryFrame>odom</odometryFrame>
      <robotBaseFrame>base_footprint</robotBaseFrame>
      <!-- robotNamespace></robotNamespace -->
      <rosDebugLevel>na</rosDebugLevel>
      <publishWheelTF>false</publishWheelTF>
      <publishWheelJointState>false</publishWheelJointState>
      <wheelAcceleration>0</wheelAcceleration>
      <wheelTorque>5</wheelTorque>
      <!-- odometrySource>encoder</odometrySource -->
      <odometrySource>world</odometrySource>
      <publishTf>1</publishTf>
    </plugin>
  </gazebo>
  <!-- WHEELS -->
  <!--WHEEL TIRE -->
  <joint name="joint_right_wheel" type="continuous">
    <parent link="base_link"/>
    <child link="right_wheel"/>
    <origin rpy="0 0 0" xyz="0.0 -0.217 0.051"/>
    <axis rpy="0 0 0" xyz="0 1 0"/>
    <limit effort="100" velocity="100"/>
    <joint_properties damping="0.0" friction="0.0"/>
  </joint>
  <link name="right_wheel">
    <visual>
      <!-- HIGH RESOLUTION WHEELS -->
      <origin rpy="0 0 0" xyz="0 0 0"/>
      <geometry>
        <mesh filename="package://rb1_base_description/meshes/wheels/wheel_rubber_6inch.dae"/>
      </geometry>
      <!-- LOW RESOLUTION WHEELS -->
    </visual>
    <collision>
      <origin rpy="1.57079632679 0 0" xyz="0 0 0"/>
      <geometry>
        <cylinder length="0.025" radius="0.076"/>
      </geometry>
    </collision>
    <inertial>
      <mass value="1.0"/>
      <origin xyz="0 0 0"/>
      <inertia ixx="0.00149608333333" ixy="0" ixz="0" iyy="0.00149608333333" iyz="0" izz="0.002888"/>
    </inertial>
  </link>
  <!-- Transmission is important to link the joints and the controller (see rb1_control/config/rb1_control.yaml)-->
  <transmission name="right_wheel_joint_trans">
    <type>transmission_interface/SimpleTransmission</type>
    <joint name="joint_right_wheel">
      <hardwareInterface>EffortJointInterface</hardwareInterface>
    </joint>
    <actuator name="right_wheel_joint_motor">
      <!-- hardwareInterface>EffortJointInterface</hardwareInterface -->
      <mechanicalReduction>1</mechanicalReduction>
      <motorTorqueConstant>10</motorTorqueConstant>
    </actuator>
  </transmission>
  <gazebo reference="right_wheel">
    <mu1 value="5.0"/>
    <mu2 value="0.5"/>
    <kp value="10000000.0"/>
    <kd value="1.0"/>
    <fdir1 value="1 0 0"/>
    <turnGravityOff>false</turnGravityOff>
  </gazebo>
  <!--WHEEL TIRE -->
  <joint name="joint_left_wheel" type="continuous">
    <parent link="base_link"/>
    <child link="left_wheel"/>
    <origin rpy="0 0 0" xyz="0.0 0.217 0.051"/>
    <axis rpy="0 0 0" xyz="0 1 0"/>
    <limit effort="100" velocity="100"/>
    <joint_properties damping="0.0" friction="0.0"/>
  </joint>
  <link name="left_wheel">
    <visual>
      <!-- HIGH RESOLUTION WHEELS -->
      <origin rpy="0 0 0" xyz="0 0 0"/>
      <geometry>
        <mesh filename="package://rb1_base_description/meshes/wheels/wheel_rubber_6inch.dae"/>
      </geometry>
      <!-- LOW RESOLUTION WHEELS -->
    </visual>
    <collision>
      <origin rpy="1.57079632679 0 0" xyz="0 0 0"/>
      <geometry>
        <cylinder length="0.025" radius="0.076"/>
      </geometry>
    </collision>
    <inertial>
      <mass value="1.0"/>
      <origin xyz="0 0 0"/>
      <inertia ixx="0.00149608333333" ixy="0" ixz="0" iyy="0.00149608333333" iyz="0" izz="0.002888"/>
    </inertial>
  </link>
  <!-- Transmission is important to link the joints and the controller (see rb1_control/config/rb1_control.yaml)-->
  <transmission name="left_wheel_joint_trans">
    <type>transmission_interface/SimpleTransmission</type>
    <joint name="joint_left_wheel">
      <hardwareInterface>EffortJointInterface</hardwareInterface>
    </joint>
    <actuator name="left_wheel_joint_motor">
      <!-- hardwareInterface>EffortJointInterface</hardwareInterface -->
      <mechanicalReduction>1</mechanicalReduction>
      <motorTorqueConstant>10</motorTorqueConstant>
    </actuator>
  </transmission>
  <gazebo reference="left_wheel">
    <mu1 value="5.0"/>
    <mu2 value="0.5"/>
    <kp value="10000000.0"/>
    <kd value="1.0"/>
    <fdir1 value="1 0 0"/>
    <turnGravityOff>false</turnGravityOff>
  </gazebo>
  <!-- OMNI DIRECTIONAL WHEELS -->
  <!--WHEEL TIRE -->
  <!-- joint name="joint_${name}_wheel" type="continuous" -->
  <joint name="joint_omni_back_wheel" type="fixed">
    <parent link="base_link"/>
    <child link="omni_back_wheel"/>
    <origin rpy="0 0 0" xyz="-0.195 0.0 0.0265"/>
    <axis rpy="0 0 0" xyz="0 1 0"/>
    <limit effort="100" velocity="100"/>
    <joint_properties damping="0.0" friction="0.0"/>
  </joint>
  <link name="omni_back_wheel">
    <visual>
      <!-- HIGH RESOLUTION WHEELS -->
      <origin rpy="0 0 0" xyz="0 0 0"/>
      <geometry>
        <mesh filename="package://rb1_base_description/meshes/wheels/wheel_omni_4inch.dae"/>
      </geometry>
      <!-- LOW RESOLUTION WHEELS -->
    </visual>
    <!-- collision>
      <origin xyz="0 0 0" rpy="${M_PI/2} 0 0" />
        <geometry>
          <cylinder length="${omni_wheel_height}" radius="${omni_wheel_radius}" />
        </geometry>
      </collision -->
    <collision>
      <origin rpy="1.57079632679 0 0" xyz="0 0 0"/>
      <geometry>
        <sphere radius="0.051"/>
      </geometry>
    </collision>
    <inertial>
      <mass value="1.0"/>
      <origin xyz="0 0 0"/>
      <inertia ixx="0.000235075" ixy="0" ixz="0" iyy="0.000235075" iyz="0" izz="0.00039015"/>
      <!-- inertia  ixx="0.001" ixy="0.0"  ixz="0.0"  iyy="0.001"  iyz="0.0"  izz="0.001" / -->
    </inertial>
  </link>
  <!-- transmission name="${name}_wheel_joint_trans">
      <type>transmission_interface/SimpleTransmission</type>
      <joint name="joint_${name}_wheel" />
      <actuator name="${name}_wheel_joint_motor">
        <hardwareInterface>EffortJointInterface</hardwareInterface>
        <mechanicalReduction>1</mechanicalReduction>
      </actuator>
    </transmission -->
  <gazebo reference="omni_back_wheel">
    <mu1 value="0.0"/>
    <mu2 value="0.0"/>
    <kp value="10000000.0"/>
    <kd value="1.0"/>
    <fdir1 value="1 0 0"/>
    <turnGravityOff>false</turnGravityOff>
  </gazebo>
  <!--WHEEL TIRE -->
  <!-- joint name="joint_${name}_wheel" type="continuous" -->
  <joint name="joint_omni_front_left_wheel" type="fixed">
    <parent link="base_link"/>
    <child link="omni_front_left_wheel"/>
    <origin rpy="0 0 0" xyz="0.133 0.144 0.0265"/>
    <axis rpy="0 0 0" xyz="0 1 0"/>
    <limit effort="100" velocity="100"/>
    <joint_properties damping="0.0" friction="0.0"/>
  </joint>
  <link name="omni_front_left_wheel">
    <visual>
      <!-- HIGH RESOLUTION WHEELS -->
      <origin rpy="0 0 0" xyz="0 0 0"/>
      <geometry>
        <mesh filename="package://rb1_base_description/meshes/wheels/wheel_omni_4inch.dae"/>
      </geometry>
      <!-- LOW RESOLUTION WHEELS -->
    </visual>
    <!-- collision>
      <origin xyz="0 0 0" rpy="${M_PI/2} 0 0" />
        <geometry>
          <cylinder length="${omni_wheel_height}" radius="${omni_wheel_radius}" />
        </geometry>
      </collision -->
    <collision>
      <origin rpy="1.57079632679 0 0" xyz="0 0 0"/>
      <geometry>
        <sphere radius="0.051"/>
      </geometry>
    </collision>
    <inertial>
      <mass value="1.0"/>
      <origin xyz="0 0 0"/>
      <inertia ixx="0.000235075" ixy="0" ixz="0" iyy="0.000235075" iyz="0" izz="0.00039015"/>
      <!-- inertia  ixx="0.001" ixy="0.0"  ixz="0.0"  iyy="0.001"  iyz="0.0"  izz="0.001" / -->
    </inertial>
  </link>
  <!-- transmission name="${name}_wheel_joint_trans">
      <type>transmission_interface/SimpleTransmission</type>
      <joint name="joint_${name}_wheel" />
      <actuator name="${name}_wheel_joint_motor">
        <hardwareInterface>EffortJointInterface</hardwareInterface>
        <mechanicalReduction>1</mechanicalReduction>
      </actuator>
    </transmission -->
  <gazebo reference="omni_front_left_wheel">
    <mu1 value="0.0"/>
    <mu2 value="0.0"/>
    <kp value="10000000.0"/>
    <kd value="1.0"/>
    <fdir1 value="1 0 0"/>
    <turnGravityOff>false</turnGravityOff>
  </gazebo>
  <!--WHEEL TIRE -->
  <!-- joint name="joint_${name}_wheel" type="continuous" -->
  <joint name="joint_omni_front_right_wheel" type="fixed">
    <parent link="base_link"/>
    <child link="omni_front_right_wheel"/>
    <origin rpy="0 0 0" xyz="0.133 -0.144 0.0265"/>
    <axis rpy="0 0 0" xyz="0 1 0"/>
    <limit effort="100" velocity="100"/>
    <joint_properties damping="0.0" friction="0.0"/>
  </joint>
  <link name="omni_front_right_wheel">
    <visual>
      <!-- HIGH RESOLUTION WHEELS -->
      <origin rpy="0 0 0" xyz="0 0 0"/>
      <geometry>
        <mesh filename="package://rb1_base_description/meshes/wheels/wheel_omni_4inch.dae"/>
      </geometry>
      <!-- LOW RESOLUTION WHEELS -->
    </visual>
    <!-- collision>
      <origin xyz="0 0 0" rpy="${M_PI/2} 0 0" />
        <geometry>
          <cylinder length="${omni_wheel_height}" radius="${omni_wheel_radius}" />
        </geometry>
      </collision -->
    <collision>
      <origin rpy="1.57079632679 0 0" xyz="0 0 0"/>
      <geometry>
        <sphere radius="0.051"/>
      </geometry>
    </collision>
    <inertial>
      <mass value="1.0"/>
      <origin xyz="0 0 0"/>
      <inertia ixx="0.000235075" ixy="0" ixz="0" iyy="0.000235075" iyz="0" izz="0.00039015"/>
      <!-- inertia  ixx="0.001" ixy="0.0"  ixz="0.0"  iyy="0.001"  iyz="0.0"  izz="0.001" / -->
    </inertial>
  </link>
  <!-- transmission name="${name}_wheel_joint_trans">
      <type>transmission_interface/SimpleTransmission</type>
      <joint name="joint_${name}_wheel" />
      <actuator name="${name}_wheel_joint_motor">
        <hardwareInterface>EffortJointInterface</hardwareInterface>
        <mechanicalReduction>1</mechanicalReduction>
      </actuator>
    </transmission -->
  <gazebo reference="omni_front_right_wheel">
    <mu1 value="0.0"/>
    <mu2 value="0.0"/>
    <kp value="10000000.0"/>
    <kd value="1.0"/>
    <fdir1 value="1 0 0"/>
    <turnGravityOff>false</turnGravityOff>
  </gazebo>
  <!-- SENSORS -->
  <!-- xacro:sensor_hokuyo_utm30lx name="hokuyo" parent="base_link">
		<origin xyz="0.210 0.0 0.305" rpy="0 0 0"/>
	</xacro:sensor_hokuyo_utm30lx -->
  <!-- xacro:sensor_hokuyo_urg04lx name="hokuyo" parent="base_link">
        <origin xyz="0.223 0.0 0.209" rpy="0 3.1416 3.1416"/>
    </xacro:sensor_hokuyo_urg04lx -->
  <joint name="hokuyo_laser_joint" type="fixed">
    <origin rpy="0 3.1416 3.1416" xyz="0.223 0.0 0.159"/>
    <parent link="base_link"/>
    <child link="hokuyo_laser_link"/>
  </joint>
  <link name="hokuyo_laser_link">
    <collision>
      <origin rpy="0 0 0" xyz="0 0 -0.05"/>
      <geometry>
        <box size="0.1 0.1 0.08"/>
      </geometry>
    </collision>
    <visual>
      <origin rpy="0 0 0" xyz="0 0 -0.05"/>
      <geometry>
        <mesh filename="package://robotnik_sensors/meshes/hokuyo_ust_10lx.dae"/>
      </geometry>
    </visual>
    <inertial>
      <mass value="1e-5"/>
      <origin rpy="0 0 0" xyz="0 0 0"/>
      <inertia ixx="1e-6" ixy="0" ixz="0" iyy="1e-6" iyz="0" izz="1e-6"/>
    </inertial>
  </link>
  <!-- Hokuyo sensor for simulation -->
  <gazebo reference="hokuyo_laser_link">
    <sensor name="hokuyo_sensor" type="ray">
      <pose>0 0 0 0 0 0</pose>
      <visualize>false</visualize>
      <update_rate>40</update_rate>
      <ray>
        <scan>
          <horizontal>
            <samples>1081</samples>
            <resolution>1</resolution>
            <min_angle>2.35619449</min_angle>
            <max_angle>-2.35619449</max_angle>
          </horizontal>
        </scan>
        <range>
          <min>0.02</min>
          <max>20.0</max>
          <resolution>0.004363323</resolution>
        </range>
        <noise>
          <type>gaussian</type>
          <mean>0.0</mean>
          <stddev>0.01</stddev>
        </noise>
      </ray>
      <plugin filename="libgazebo_ros_laser.so" name="gazebo_ros_head_hokuyo_controller">
        <topicName>hokuyo/scan</topicName>
        <frameName>hokuyo_laser_link</frameName>
      </plugin>
    </sensor>
  </gazebo>
  <joint name="imu_joint" type="fixed">
    <axis xyz="1 0 0"/>
    <!--origin xyz="0 0 0.2825"/-->
    <origin rpy="0 0 0" xyz="-0.18 0.0 0.170"/>
    <parent link="base_link"/>
    <child link="imu_link"/>
  </joint>
  <link name="imu_link">
    <inertial>
      <mass value="0.001"/>
      <origin rpy="0 0 0" xyz="0 0 0"/>
      <inertia ixx="0.0001" ixy="0" ixz="0" iyy="0.000001" iyz="0" izz="0.0001"/>
    </inertial>
    <visual>
      <origin rpy="0 0 0" xyz="0 0 0"/>
      <geometry>
        <box size="0.001 0.001 0.001"/>
      </geometry>
    </visual>
    <collision>
      <origin rpy="0 0 0" xyz="0 0 0"/>
      <geometry>
        <box size=".001 .001 .001"/>
      </geometry>
    </collision>
  </link>
  <gazebo>
    <plugin filename="libgazebo_ros_imu.so" name="ros_imu">
      <topicName>imu_data</topicName>
      <bodyName>imu_link</bodyName>
      <serviceName>imu_service</serviceName>
      <gaussianNoise>0.005</gaussianNoise>
    </plugin>
  </gazebo>
  <!--
    <xacro:sensor_kinect name="kinect" parent="base_link">
        <origin xyz="0.3 0.0 0.16" rpy="0 0 0"/> 
    </xacro:sensor_kinect>  
-->
  <!-- Import RB1 torso -->
  <!-- ***************** -->
  <!-- Imported elements -->
  <!-- ***************** -->
  <!-- First we import all posible elements defined in the urdf.xacro files. All these elements are defined as macro:xacros -->
  <!-- Import RB1 arm elements -->
  <!-- xacro:include filename="$(find rb1_torso_description)/urdf/rb1_torso_3dof.gazebo.xacro" / -->
  <!-- Import all available sensors -->
  <!-- This file unifies all sensors that can be used on simulation, defined as xacro:macros -->
  <!-- Axis p5512 -->
  <!-- Axis m5013 -->
  <!-- Fotonic -->
  <!-- GPS -->
  <!-- Hokuyo urg04lx -->
  <!-- Hokuyo utm30lx -->
  <!-- Hokuyo ust10lx -->
  <!-- Imu -->
  <!-- Kinect -->
  <!-- Asus Xtion PRO -->
  <!-- Xacro properties -->
  <!-- Hokuyo 3d -->
  <!-- KinectV2 -->
  <!-- ***************** -->
  <!-- Global parameters -->
  <!-- ***************** -->
  <!-- Flag to select the high or low quality model -->
  <!-- RB-1 torso -->
  <!-- Robot mechanical and motor parameters -->
  <xacro:property name="PI" value="3.1415926535897931"/>
  <!-- BASE_LINK -->
  <link name="base_link_rb1_torso">
  </link>
  <link name="link1_torso">
    <inertial>
      <mass value="3.0"/>
      <origin xyz="0 0 0"/>
      <inertia ixx="1.0" ixy="0.0" ixz="0.0" iyy="1.0" iyz="0.0" izz="1.0"/>
    </inertial>
    <visual>
      <origin rpy="0 0 0" xyz="0 0 0"/>
      <geometry>
        <mesh filename="package://rb1_torso_description/meshes/torsos/rb1_lower.dae"/>
      </geometry>
      <material name="darkgrey">
        <color rgba="0.1 0.1 0.1 1"/>
      </material>
    </visual>
    <collision>
      <origin rpy="0 0 0 " xyz="0 0 0"/>
      <geometry>
        <mesh filename="package://rb1_torso_description/meshes/torsos/rb1_lower.dae"/>
      </geometry>
    </collision>
  </link>
  <joint name="j0_rb1_torso" type="fixed">
    <origin rpy="0.0 0.0 0.0" xyz="0.0 0.0 0.0"/>
    <parent link="base_link_rb1_torso"/>
    <child link="link1_torso"/>
    <axis xyz="0 0 0"/>
  </joint>
  <link name="link2_torso">
    <inertial>
      <mass value="2.0"/>
      <origin xyz="0 0 0"/>
      <inertia ixx="1.0" ixy="0.0" ixz="0.0" iyy="1.0" iyz="0.0" izz="1.0"/>
    </inertial>
    <visual>
      <origin rpy="0 0 0" xyz="0 0 0"/>
      <geometry>
        <mesh filename="package://rb1_torso_description/meshes/torsos/rb1_upper.dae"/>
      </geometry>
      <material name="darkgrey">
        <color rgba="0.1 0.1 0.1 1"/>
      </material>
    </visual>
    <collision>
      <origin rpy="0 0 0 " xyz="0 0 0"/>
      <geometry>
        <mesh filename="package://rb1_torso_description/meshes/torsos/rb1_upper.dae"/>
      </geometry>
    </collision>
  </link>
  <joint name="j1_torso" type="prismatic">
    <origin rpy="0.0 0.0 0.0" xyz="0 0 0"/>
    <parent link="link1_torso"/>
    <child link="link2_torso"/>
    <axis xyz="0 0 1"/>
    <limit effort="5000.0" lower="0.0" upper="0.36" velocity="1.0"/>
    <dynamics damping="0.7" friction="0.5"/>
  </joint>
  <transmission name="j1_torso_trans">
    <type>transmission_interface/SimpleTransmission</type>
    <joint name="j1_torso">
      <hardwareInterface>EffortJointInterface</hardwareInterface>
    </joint>
    <actuator name="j1_torso_motor">
      <mechanicalReduction>320.0</mechanicalReduction>
      <motorTorqueConstant>1.0</motorTorqueConstant>
    </actuator>
  </transmission>
  <link name="link1_head">
    <inertial>
      <mass value="1.0"/>
      <origin xyz="0 0 0"/>
      <inertia ixx="1.0" ixy="0.0" ixz="0.0" iyy="1.0" iyz="0.0" izz="1.0"/>
    </inertial>
    <visual>
      <origin rpy="0 0 0" xyz="0 0 0"/>
      <geometry>
        <mesh filename="package://rb1_torso_description/meshes/heads/head1.dae"/>
      </geometry>
      <material name="darkgrey">
        <color rgba="0.1 0.1 0.1 1"/>
      </material>
    </visual>
    <collision>
      <origin rpy="0 0 0 " xyz="0 0 0"/>
      <geometry>
        <mesh filename="package://rb1_torso_description/meshes/heads/head1.dae"/>
      </geometry>
    </collision>
  </link>
  <joint name="j1_head" type="revolute">
    <origin rpy="0.0 0.0 0.0" xyz="0.010 0.0 0.940"/>
    <parent link="link2_torso"/>
    <child link="link1_head"/>
    <axis xyz="0 0 1"/>
    <limit effort="3.0" lower="-1.57079632679" upper="1.57079632679" velocity="2.98452"/>
    <dynamics damping="0.7" friction="0.5"/>
  </joint>
  <transmission name="j1_head_trans">
    <type>transmission_interface/SimpleTransmission</type>
    <joint name="j1_head">
      <hardwareInterface>EffortJointInterface</hardwareInterface>
    </joint>
    <actuator name="j1_head_motor">
      <mechanicalReduction>320.0</mechanicalReduction>
      <motorTorqueConstant>1.0</motorTorqueConstant>
    </actuator>
  </transmission>
  <link name="link2_head">
    <inertial>
      <mass value="1.0"/>
      <origin xyz="0 0 0"/>
      <inertia ixx="1.0" ixy="0.0" ixz="0.0" iyy="1.0" iyz="0.0" izz="1.0"/>
    </inertial>
    <visual>
      <origin rpy="0 0 0" xyz="0 0 0"/>
      <geometry>
        <mesh filename="package://rb1_torso_description/meshes/heads/head2.dae"/>
      </geometry>
      <material name="darkgrey">
        <color rgba="0.1 0.1 0.1 1"/>
      </material>
    </visual>
    <collision>
      <origin rpy="0 0 0 " xyz="0 0 0"/>
      <geometry>
        <mesh filename="package://rb1_torso_description/meshes/heads/head2.dae"/>
      </geometry>
    </collision>
  </link>
  <joint name="j2_head" type="revolute">
    <origin rpy="0.0 0.0 0.0" xyz="0.105 0.0 0.0"/>
    <parent link="link1_head"/>
    <child link="link2_head"/>
    <!-- check -->
    <!-- axis xyz="0 1 0" / -->
    <axis xyz="0 -1 0"/>
    <limit effort="3.0" lower="-0.785398163397" upper="0.785398163397" velocity="2.98452"/>
    <dynamics damping="0.7" friction="0.5"/>
  </joint>
  <transmission name="j2_head_trans">
    <type>transmission_interface/SimpleTransmission</type>
    <joint name="j2_head">
      <hardwareInterface>EffortJointInterface</hardwareInterface>
    </joint>
    <actuator name="j2_head_motor">
      <mechanicalReduction>320.0</mechanicalReduction>
      <motorTorqueConstant>1.0</motorTorqueConstant>
    </actuator>
  </transmission>
  <!-- Ixtion sensor in head -->
  <joint name="xtion_head_cam_rgb_joint" type="fixed">
    <origin rpy="0 0 0" xyz="0.055 0.000 0.028"/>
    <parent link="link2_head"/>
    <child link="xtion_head_cam_rgb_frame"/>
  </joint>
  <link name="xtion_head_cam_rgb_frame">
    <inertial>
      <mass value="0.001"/>
      <origin xyz="0 0 0"/>
      <inertia ixx="0.0001" ixy="0.0" ixz="0.0" iyy="0.0001" iyz="0.0" izz="0.0001"/>
    </inertial>
  </link>
  <joint name="xtion_head_cam_rgb_optical_joint" type="fixed">
    <origin rpy="-1.57079632679 0 -1.57079632679" xyz="0 0 0"/>
    <parent link="xtion_head_cam_rgb_frame"/>
    <child link="xtion_head_cam_rgb_optical_frame"/>
  </joint>
  <link name="xtion_head_cam_rgb_optical_frame">
    <inertial>
      <mass value="0.001"/>
      <origin xyz="0 0 0"/>
      <inertia ixx="0.0001" ixy="0.0" ixz="0.0" iyy="0.0001" iyz="0.0" izz="0.0001"/>
    </inertial>
  </link>
  <joint name="xtion_head_cam_joint" type="fixed">
    <origin rpy="0 0 0" xyz="0 -0.022 0"/>
    <parent link="xtion_head_cam_rgb_frame"/>
    <child link="xtion_head_cam_link"/>
  </joint>
  <link name="xtion_head_cam_link">
    <visual>
      <origin rpy="-1.57079632679 -3.14159265359 -1.57079632679" xyz="-0.01 0 0"/>
      <geometry>
        <mesh filename="package://robotnik_sensors/meshes/asus_xtion_pro_live.dae" scale="0.001 0.001 0.001"/>
      </geometry>
    </visual>
    <collision>
      <origin rpy="0 0 0" xyz="0.0 0.0 0.0"/>
      <geometry>
        <box size="0.0730 .2760 0.0720"/>
      </geometry>
    </collision>
    <inertial>
      <mass value="0.01"/>
      <origin xyz="0 0 0"/>
      <inertia ixx="0.001" ixy="0.0" ixz="0.0" iyy="0.001" iyz="0.0" izz="0.001"/>
    </inertial>
  </link>
  <joint name="xtion_head_cam_depth_joint" type="fixed">
    <origin rpy="0 0 0" xyz="0 0.027 0"/>
    <parent link="xtion_head_cam_rgb_frame"/>
    <child link="xtion_head_cam_depth_frame"/>
  </joint>
  <link name="xtion_head_cam_depth_frame">
    <inertial>
      <mass value="0.01"/>
      <origin xyz="0 0 0"/>
      <inertia ixx="0.001" ixy="0.0" ixz="0.0" iyy="0.001" iyz="0.0" izz="0.001"/>
    </inertial>
  </link>
  <joint name="xtion_head_cam_depth_optical_joint" type="fixed">
    <origin rpy="-1.57079632679 0 -1.57079632679" xyz="0 0 0"/>
    <parent link="xtion_head_cam_depth_frame"/>
    <child link="xtion_head_cam_depth_optical_frame"/>
  </joint>
  <link name="xtion_head_cam_depth_optical_frame">
    <inertial>
      <mass value="0.001"/>
      <origin xyz="0 0 0"/>
      <inertia ixx="0.0001" ixy="0.0" ixz="0.0" iyy="0.0001" iyz="0.0" izz="0.0001"/>
    </inertial>
  </link>
  <!-- RGBD sensor for simulation, same as Kinect -->
  <gazebo reference="xtion_head_cam_depth_frame">
    <sensor name="cam" type="depth">
      <always_on>true</always_on>
      <update_rate>20.0</update_rate>
      <camera>
        <horizontal_fov>1.0471975512</horizontal_fov>
        <image>
          <format>R8G8B8</format>
          <width>640</width>
          <height>480</height>
        </image>
        <clip>
          <near>0.05</near>
          <far>3.5</far>
        </clip>
      </camera>
      <plugin filename="libgazebo_ros_openni_kinect.so" name="xtion_pro_cam_controller">
        <cameraName>xtion_head</cameraName>
        <alwaysOn>true</alwaysOn>
        <updateRate>15</updateRate>
        <imageTopicName>rgb/image_raw</imageTopicName>
        <depthImageTopicName>depth/image_raw</depthImageTopicName>
        <pointCloudTopicName>depth/points</pointCloudTopicName>
        <cameraInfoTopicName>rgb/camera_info</cameraInfoTopicName>
        <depthImageCameraInfoTopicName>depth/camera_info</depthImageCameraInfoTopicName>
        <frameName>xtion_head_cam_depth_optical_frame</frameName>
        <baseline>0.1</baseline>
        <distortion_k1>0.0</distortion_k1>
        <distortion_k2>0.0</distortion_k2>
        <distortion_k3>0.0</distortion_k3>
        <distortion_t1>0.0</distortion_t1>
        <distortion_t2>0.0</distortion_t2>
        <pointCloudCutoff>0.4</pointCloudCutoff>
      </plugin>
    </sensor>
  </gazebo>
  <!-- Gazebo ros control plugins -->
  <!-- xacro:ros_control/ -->
  <!-- Import RB1 arm -->
  <!-- ***************** -->
  <!-- Imported elements -->
  <!-- ***************** -->
  <!-- First we import all posible elements defined in the urdf.xacro files. All these elements are defined as macro:xacros -->
  <!-- Import RB1 arm elements -->
  <!-- Import all available sensors -->
  <!-- xacro:include filename="$(find rb1_arm_description)/urdf/sensors/all_sensors.urdf.xacro" / -->
  <gazebo reference="base_link_gripper">
    <material>Gazebo/Grey</material>
  </gazebo>
  <gazebo reference="link_finger1">
    <material>Gazebo/Black</material>
  </gazebo>
  <gazebo reference="link_finger2">
    <material>Gazebo/Black</material>
  </gazebo>
  <link name="base_link_gripper">
    <inertial>
      <origin rpy="0 0 0" xyz="0.0 0.0 0.0"/>
      <mass value="0.257"/>
      <inertia ixx="0.000131356" ixy="0.0" ixz="0.000000083" iyy="0.000130775" iyz="0.0" izz="0.00006918"/>
    </inertial>
    <visual>
      <origin rpy="0 0 0" xyz="0 0 0"/>
      <geometry>
        <mesh filename="package://rb1_arm_description/meshes/grippers/v1/gripper_motor.dae"/>
      </geometry>
      <material name="">
        <color rgba="0.79216 0.81961 0.93333 1"/>
      </material>
    </visual>
    <collision>
      <origin rpy="0 0 0" xyz="0 0 0"/>
      <geometry>
        <mesh filename="package://rb1_arm_description/meshes/grippers/v1/gripper_motor.dae"/>
      </geometry>
      <contact_coefficients kd="1.0" kp="1000.0" mu="0"/>
    </collision>
  </link>
  <link name="link_finger1">
    <inertial>
      <origin rpy="0 0 0" xyz="0.0 0.0 0.0"/>
      <mass value="0.1264"/>
      <inertia ixx="0.000097351" ixy="0.000056737" ixz="0.000000245" iyy="0.000315015" iyz="0.000001224" izz="0.000319853"/>
    </inertial>
    <visual>
      <origin rpy="0 0 0" xyz="0 0 0"/>
      <geometry>
        <mesh filename="package://rb1_arm_description/meshes/grippers/v1/gripper_link1.dae"/>
      </geometry>
      <material name="">
        <color rgba="0.792156862745098 0.819607843137255 0.933333333333333 1"/>
      </material>
    </visual>
    <collision>
      <origin rpy="0 0 0" xyz="0 0 0"/>
      <geometry>
        <mesh filename="package://rb1_arm_description/meshes/grippers/v1/gripper_link1.dae"/>
      </geometry>
    </collision>
  </link>
  <joint name="jg1" type="fixed">
    <origin rpy="0.0 0.0 0.0" xyz="0.0 0.0 0"/>
    <parent link="base_link_gripper"/>
    <child link="link_finger1"/>
  </joint>
  <link name="link_finger2">
    <inertial>
      <origin rpy="0 0 0" xyz="0.0 0.0 0.0"/>
      <mass value="0.0633"/>
      <inertia ixx="0.000062574" ixy="-0.00005905" ixz="0.000009803" iyy="0.000292473" iyz="-0.00000366" izz="0.00027232"/>
    </inertial>
    <visual>
      <origin rpy="0 0 0" xyz="0 0 0"/>
      <geometry>
        <mesh filename="package://rb1_arm_description/meshes/grippers/v1/gripper_link2.dae"/>
      </geometry>
      <material name="">
        <color rgba="0.792156862745098 0.819607843137255 0.933333333333333 1"/>
      </material>
    </visual>
    <collision>
      <origin rpy="0 0 0" xyz="0 0 0"/>
      <geometry>
        <mesh filename="package://rb1_arm_description/meshes/grippers/v1/gripper_link1.dae"/>
      </geometry>
    </collision>
  </link>
  <joint name="jg2" type="revolute">
    <origin rpy="0.0 0.0 0.0" xyz="0.0 0.0 0"/>
    <parent link="base_link_gripper"/>
    <child link="link_finger2"/>
    <axis xyz="0 0 1"/>
    <limit effort="3.0" lower="-0.7" upper="0.0" velocity="2.98452"/>
    <dynamics damping="0.7" friction="0.5"/>
  </joint>
  <transmission name="jg2_trans">
    <type>transmission_interface/SimpleTransmission</type>
    <joint name="jg2">
      <hardwareInterface>EffortJointInterface</hardwareInterface>
    </joint>
    <actuator name="jg2_motor">
      <mechanicalReduction>304.0</mechanicalReduction>
      <motorTorqueConstant>3.0</motorTorqueConstant>
    </actuator>
  </transmission>
  <!-- Joint elements -->
  <joint name="gripper_joint" type="fixed">
    <origin rpy="0.0 0.0 0.0" xyz="0.055 0.0 0.0"/>
    <parent link="end_effector_rb1_arm"/>
    <child link="base_link_gripper"/>
    <axis xyz="1 0 0"/>
  </joint>
  <!-- ***************** -->
  <!-- Global parameters -->
  <!-- ***************** -->
  <!-- Flag to select the high or low quality model -->
  <!-- RB-1 arm -->
  <!-- Robot mechanical and motor parameters -->
  <xacro:property name="PI" value="3.1415926535897931"/>
  <!-- BASE_LINK -->
  <!-- link
      name="base_link_rb1_arm">
    </link>
	<joint
		  name="j1_rb1_arm"
		  type="fixed">
		<origin
		  xyz="0.0 0.0 0.0"
		  rpy="0.0 0.0 0.0" />
		<parent
		  link="base_link_rb1_arm" />
		<child
		  link="link01_rb1_arm" />
		<axis
		  xyz="0 0 0" />
	</joint -->
  <!-- 01 -->
  <!-- link name="link01_rb1_arm" -->
  <link name="base_link_rb1_arm">
    <inertial>
      <mass value="0.506"/>
      <origin xyz="-0.05161 0 -0.003"/>
      <inertia ixx="0.0014526484" ixy="0.0" ixz="-8.792613e-005" iyx="0.0" iyy="0.0018217854" iyz="0.0" izz="0.0008987159"/>
    </inertial>
    <visual>
      <origin rpy="0 0 0" xyz="0 0 0"/>
      <geometry>
        <mesh filename="package://rb1_arm_description/meshes/arms/armRB1_1_link.dae"/>
      </geometry>
      <material name="darkgrey">
        <color rgba="0.1 0.1 0.1 1"/>
      </material>
    </visual>
    <collision>
      <origin rpy="0 0 0 " xyz="0 0 0"/>
      <geometry>
        <mesh filename="package://rb1_arm_description/meshes/arms/armRB1_1_link.dae"/>
      </geometry>
    </collision>
  </link>
  <link name="motor01_rb1_arm">
    <inertial>
      <mass value="0.855"/>
      <origin xyz="0 0 0.00693"/>
      <!--inertia  ixx="0.01" ixy="0.0"  ixz="0.0"  iyy="0.01"  iyz="0.0"  izz="0.01" /-->
      <inertia ixx="0.001211476" ixy="0.0" ixz="6.05332e-006" iyy="0.001211334" iyz="0.0" izz="0.0003787678"/>
    </inertial>
    <visual>
      <origin rpy="0 0 0" xyz="0 0 0"/>
      <geometry>
        <mesh filename="package://rb1_arm_description/meshes/arms/armRB1_1_motor.dae"/>
      </geometry>
      <material name="darkgrey">
        <color rgba="0.1 0.1 0.1 1"/>
      </material>
    </visual>
    <collision>
      <origin rpy="0 0 0 " xyz="0 0 0"/>
      <geometry>
        <mesh filename="package://rb1_arm_description/meshes/arms/armRB1_1_motor.dae"/>
      </geometry>
    </collision>
  </link>
  <joint name="j01m_rb1_arm" type="fixed">
    <origin rpy="0.0 0.0 0.0" xyz="0.0 0.0 0.0"/>
    <!-- parent
		  link="link01_rb1_arm" / -->
    <parent link="base_link_rb1_arm"/>
    <child link="motor01_rb1_arm"/>
    <axis xyz="0 0 0"/>
  </joint>
  <!-- JOINT 1 -->
  <link name="link12_rb1_arm">
    <inertial>
      <mass value="0.7"/>
      <origin xyz="0.07155 0.00229 -0.00028"/>
      <inertia ixx="0.0018430902" ixy="0.0001075379" ixz="2.683183e-005" iyy="0.0023530852" iyz="4.5192e-007" izz="0.0016327528"/>
    </inertial>
    <visual>
      <origin rpy="0 0 0" xyz="0 0 0"/>
      <geometry>
        <mesh filename="package://rb1_arm_description/meshes/arms/armRB1_12_link.dae"/>
      </geometry>
      <material name="darkgrey">
        <color rgba="0.1 0.1 0.1 1"/>
      </material>
    </visual>
    <collision>
      <origin rpy="0 0 0 " xyz="0 0 0"/>
      <geometry>
        <mesh filename="package://rb1_arm_description/meshes/arms/armRB1_12_link.dae"/>
      </geometry>
    </collision>
  </link>
  <link name="motor12_rb1_arm">
    <inertial>
      <mass value="0.855"/>
      <origin xyz="0.13488 -0.00693 0"/>
      <inertia ixx="0.001211476" ixy="-6.05332e-006" ixz="0.0" iyy="0.0003787678" iyz="0.0" izz="0.001211334"/>
    </inertial>
    <visual>
      <origin rpy="0 0 0" xyz="0 0 0"/>
      <geometry>
        <mesh filename="package://rb1_arm_description/meshes/arms/armRB1_12_motor.dae"/>
      </geometry>
      <material name="darkgrey">
        <color rgba="0.1 0.1 0.1 1"/>
      </material>
    </visual>
    <collision>
      <origin rpy="0 0 0 " xyz="0 0 0"/>
      <geometry>
        <mesh filename="package://rb1_arm_description/meshes/arms/armRB1_12_motor.dae"/>
      </geometry>
    </collision>
  </link>
  <joint name="j12m_rb1_arm" type="fixed">
    <origin rpy="0.0 0.0 0.0" xyz="0.0 0.0 0.0"/>
    <parent link="link12_rb1_arm"/>
    <child link="motor12_rb1_arm"/>
    <axis xyz="0 0 0"/>
  </joint>
  <joint name="j1" type="revolute">
    <origin rpy="0.0 0.0 0.0" xyz="0 0 0"/>
    <!-- parent link="link01_rb1_arm" /-->
    <parent link="base_link_rb1_arm"/>
    <child link="link12_rb1_arm"/>
    <axis xyz="0 0 1"/>
    <limit effort="60.0" lower="-1.55" upper="1.55" velocity="2.9217"/>
    <dynamics damping="0.7" friction="0.5"/>
  </joint>
  <transmission name="j1_trans">
    <type>transmission_interface/SimpleTransmission</type>
    <joint name="j1">
      <hardwareInterface>EffortJointInterface</hardwareInterface>
    </joint>
    <actuator name="j1_motor">
      <!-- hardwareInterface>EffortJointInterface</hardwareInterface -->
      <mechanicalReduction>502.0</mechanicalReduction>
      <motorTorqueConstant>50.0</motorTorqueConstant>
    </actuator>
  </transmission>
  <!-- JOINT 2 -->
  <link name="link23_rb1_arm">
    <inertial>
      <mass value="0.429"/>
      <origin xyz="0.06076 0 -0.00014"/>
      <inertia ixx="0.0011551458" ixy="-6.3e-010" ixz="2.519546e-005" iyy="0.0015754353" iyz="-7.6e-010" izz="0.0007798411"/>
    </inertial>
    <visual>
      <origin rpy="0 0 0" xyz="0 0 0"/>
      <geometry>
        <mesh filename="package://rb1_arm_description/meshes/arms/armRB1_23_link.dae"/>
      </geometry>
      <material name="darkgrey">
        <color rgba="0.1 0.1 0.1 1"/>
      </material>
    </visual>
    <collision>
      <origin rpy="0 0 0 " xyz="0 0 0"/>
      <geometry>
        <mesh filename="package://rb1_arm_description/meshes/arms/armRB1_23_link.dae"/>
      </geometry>
    </collision>
  </link>
  <link name="motor23_rb1_arm">
    <inertial>
      <mass value="0.732"/>
      <origin xyz="0.11598 0 0.00014"/>
      <!--inertia  ixx="0.01" ixy="0.0"  ixz="0.0"  iyy="0.01"  iyz="0.0"  izz="0.01" /-->
      <inertia ixx="0.02661733557" ixy="0.00029270634" ixz="0.00392189887" iyy="0.02844355207" iyz="0.0010838933" izz="0.01248008322"/>
    </inertial>
    <visual>
      <origin rpy="0 0 0" xyz="0 0 0"/>
      <geometry>
        <mesh filename="package://rb1_arm_description/meshes/arms/armRB1_23_motor.dae"/>
      </geometry>
      <material name="darkgrey">
        <color rgba="0.1 0.1 0.1 1"/>
      </material>
    </visual>
    <collision>
      <origin rpy="0 0 0 " xyz="0 0 0"/>
      <geometry>
        <mesh filename="package://rb1_arm_description/meshes/arms/armRB1_23_motor.dae"/>
      </geometry>
    </collision>
  </link>
  <joint name="j23m_rb1_arm" type="fixed">
    <origin rpy="0.0 0.0 0.0" xyz="0.0 0.0 0.0"/>
    <parent link="link23_rb1_arm"/>
    <child link="motor23_rb1_arm"/>
    <axis xyz="0 0 0"/>
  </joint>
  <joint name="j2" type="revolute">
    <origin rpy="1.57079632679 0.0 0.0" xyz="0.135 0 0"/>
    <parent link="link12_rb1_arm"/>
    <child link="link23_rb1_arm"/>
    <!-- check -->
    <!-- axis xyz="0 0 -1" / -->
    <axis xyz="0 0 1"/>
    <limit effort="60.0" lower="-1.95" upper="1.55" velocity="2.9217"/>
    <dynamics damping="0.7" friction="0.5"/>
  </joint>
  <transmission name="j2_trans">
    <type>transmission_interface/SimpleTransmission</type>
    <joint name="j2">
      <hardwareInterface>EffortJointInterface</hardwareInterface>
    </joint>
    <actuator name="j2_motor">
      <mechanicalReduction>502.0</mechanicalReduction>
      <motorTorqueConstant>50.0</motorTorqueConstant>
    </actuator>
  </transmission>
  <!-- JOINT 3 -->
  <link name="link34_rb1_arm">
    <inertial>
      <mass value="0.351"/>
      <origin xyz="-0.07306 0 -0.00466"/>
      <inertia ixx="0.0003749308" ixy="0.0" ixz="-0.0001258961" iyy="0.0010047174" iyz="0.0" izz="0.0009318091"/>
    </inertial>
    <visual>
      <origin rpy="0 0 0" xyz="0 0 0"/>
      <geometry>
        <mesh filename="package://rb1_arm_description/meshes/arms/armRB1_34_link.dae"/>
      </geometry>
      <material name="darkgrey">
        <color rgba="0.1 0.1 0.1 1"/>
      </material>
    </visual>
    <collision>
      <origin rpy="0 0 0 " xyz="0 0 0"/>
      <geometry>
        <mesh filename="package://rb1_arm_description/meshes/arms/armRB1_34_link.dae"/>
      </geometry>
    </collision>
  </link>
  <link name="motor34_rb1_arm">
    <inertial>
      <mass value="0.732"/>
      <origin xyz="0.00014 0 0.00698"/>
      <inertia ixx="0.0007977173" ixy="0.0" ixz="-5.17658e-006" iyy="0.000797409" iyz="0.0" izz="0.0003233065"/>
    </inertial>
    <visual>
      <origin rpy="0 0 0" xyz="0 0 0"/>
      <geometry>
        <mesh filename="package://rb1_arm_description/meshes/arms/armRB1_34_motor.dae"/>
      </geometry>
      <material name="darkgrey">
        <color rgba="0.1 0.1 0.1 1"/>
      </material>
    </visual>
    <collision>
      <origin rpy="0 0 0 " xyz="0 0 0"/>
      <geometry>
        <mesh filename="package://rb1_arm_description/meshes/arms/armRB1_34_motor.dae"/>
      </geometry>
    </collision>
  </link>
  <joint name="j34m_rb1_arm" type="fixed">
    <origin rpy="0.0 0.0 0.0" xyz="0.0 0.0 0.0"/>
    <parent link="link34_rb1_arm"/>
    <child link="motor34_rb1_arm"/>
    <axis xyz="0 0 0"/>
  </joint>
  <joint name="j3" type="revolute">
    <origin rpy="0.0 0.0 0.0" xyz="0.310 0 0"/>
    <parent link="link23_rb1_arm"/>
    <child link="link34_rb1_arm"/>
    <axis xyz="1 0 0"/>
    <limit effort="35.0" lower="-3.13" upper="3.13" velocity="3.1527"/>
    <dynamics damping="0.7" friction="0.5"/>
  </joint>
  <transmission name="j3_trans">
    <type>transmission_interface/SimpleTransmission</type>
    <joint name="j3">
      <hardwareInterface>EffortJointInterface</hardwareInterface>
    </joint>
    <actuator name="j3_motor">
      <mechanicalReduction>502.0</mechanicalReduction>
      <motorTorqueConstant>50.0</motorTorqueConstant>
    </actuator>
  </transmission>
  <!-- JOINT 4 -->
  <link name="link45_rb1_arm">
    <inertial>
      <mass value="0.388"/>
      <origin xyz="0.05882 0 -0.00029"/>
      <inertia ixx="0.0008598409" ixy="-6.1e-010" ixz="2.148066e-005" iyy="0.00127317" iyz="-6.6e-010" izz="0.0007358862"/>
    </inertial>
    <visual>
      <origin rpy="0 0 0" xyz="0 0 0"/>
      <geometry>
        <mesh filename="package://rb1_arm_description/meshes/arms/armRB1_45_link.dae"/>
      </geometry>
      <material name="darkgrey">
        <color rgba="0.1 0.1 0.1 1"/>
      </material>
    </visual>
    <collision>
      <origin rpy="0 0 0 " xyz="0 0 0"/>
      <geometry>
        <mesh filename="package://rb1_arm_description/meshes/arms/armRB1_45_link.dae"/>
      </geometry>
    </collision>
  </link>
  <link name="motor45_rb1_arm">
    <inertial>
      <mass value="0.732"/>
      <origin xyz="0.11398 0 0.00014"/>
      <inertia ixx="0.0003233065" ixy="0.0" ixz="-5.17658e-006" iyy="0.000797409" iyz="0.0" izz="0.0007977173"/>
    </inertial>
    <visual>
      <origin rpy="0 0 0" xyz="0 0 0"/>
      <geometry>
        <mesh filename="package://rb1_arm_description/meshes/arms/armRB1_45_motor.dae"/>
      </geometry>
      <material name="darkgrey">
        <color rgba="0.1 0.1 0.1 1"/>
      </material>
    </visual>
    <collision>
      <origin rpy="0 0 0 " xyz="0 0 0"/>
      <geometry>
        <mesh filename="package://rb1_arm_description/meshes/arms/armRB1_45_motor.dae"/>
      </geometry>
    </collision>
  </link>
  <joint name="j45m_rb1_arm" type="fixed">
    <origin rpy="0.0 0.0 0.0" xyz="0.0 0.0 0.0"/>
    <parent link="link45_rb1_arm"/>
    <child link="motor45_rb1_arm"/>
    <axis xyz="0 0 0"/>
  </joint>
  <joint name="j4" type="revolute">
    <origin rpy="0.0 0.0 0.0" xyz="0 0 0"/>
    <parent link="link34_rb1_arm"/>
    <child link="link45_rb1_arm"/>
    <axis xyz="0 0 1"/>
    <limit effort="35.0" lower="-1.95" upper="1.95" velocity="3.1527"/>
    <dynamics damping="0.7" friction="0.5"/>
  </joint>
  <transmission name="j4_trans">
    <type>transmission_interface/SimpleTransmission</type>
    <joint name="j4">
      <hardwareInterface>EffortJointInterface</hardwareInterface>
    </joint>
    <actuator name="j4_motor">
      <mechanicalReduction>502.0</mechanicalReduction>
      <motorTorqueConstant>5.0</motorTorqueConstant>
    </actuator>
  </transmission>
  <!-- JOINT 5 -->
  <link name="link56_rb1_arm">
    <inertial>
      <mass value="0.3559"/>
      <origin xyz="-0.05587 0 0.0189"/>
      <inertia ixx="0.0006065534" ixy="-3.8893e-007" ixz="8.365509e-005" iyy="0.0012291083" iyz="-2.9944e-007" izz="0.000821452"/>
    </inertial>
    <visual>
      <origin rpy="0 0 0" xyz="0 0 0"/>
      <geometry>
        <mesh filename="package://rb1_arm_description/meshes/arms/armRB1_56_link.dae"/>
      </geometry>
      <material name="darkgrey">
        <color rgba="0.1 0.1 0.1 1"/>
      </material>
    </visual>
    <collision>
      <origin rpy="0 0 0 " xyz="0 0 0"/>
      <geometry>
        <mesh filename="package://rb1_arm_description/meshes/arms/armRB1_56_link.dae"/>
      </geometry>
    </collision>
  </link>
  <link name="motor56_rb1_arm">
    <inertial>
      <mass value="0.34"/>
      <origin xyz="0 0 0"/>
      <inertia ixx="0.0002196171" ixy="0.0" ixz="2.3781e-006" iyy="0.0002200183" iyz="0.0" izz="9.300873e-005"/>
    </inertial>
    <visual>
      <origin rpy="0 0 0" xyz="0 0 0"/>
      <geometry>
        <mesh filename="package://rb1_arm_description/meshes/arms/armRB1_56_motor.dae"/>
      </geometry>
      <material name="darkgrey">
        <color rgba="0.1 0.1 0.1 1"/>
      </material>
    </visual>
    <collision>
      <origin rpy="0 0 0 " xyz="0 0 0"/>
      <geometry>
        <mesh filename="package://rb1_arm_description/meshes/arms/armRB1_56_motor.dae"/>
      </geometry>
    </collision>
  </link>
  <joint name="j56m_rb1_arm" type="fixed">
    <origin rpy="0.0 0.0 0.0" xyz="0.0 0.0 0.0"/>
    <parent link="link56_rb1_arm"/>
    <child link="motor56_rb1_arm"/>
    <axis xyz="0 0 0"/>
  </joint>
  <joint name="j5" type="revolute">
    <origin rpy="0.0 0.0 0.0" xyz="0.285 0 0"/>
    <parent link="link45_rb1_arm"/>
    <child link="link56_rb1_arm"/>
    <axis xyz="1 0 0"/>
    <limit effort="35.0" lower="-3.13" upper="3.13" velocity="3.1527"/>
    <dynamics damping="0.7" friction="0.5"/>
  </joint>
  <transmission name="j5_trans">
    <type>transmission_interface/SimpleTransmission</type>
    <joint name="j5">
      <hardwareInterface>EffortJointInterface</hardwareInterface>
    </joint>
    <actuator name="j5_motor">
      <mechanicalReduction>502.0</mechanicalReduction>
      <motorTorqueConstant>5.0</motorTorqueConstant>
    </actuator>
  </transmission>
  <!-- JOINT 6 -->
  <link name="link67_rb1_arm">
    <inertial>
      <mass value="0.055"/>
      <origin xyz="-0.00099 0 0.0035"/>
      <inertia ixx="4.888031e-005" ixy="0.0" ixz="1.5733e-007" iyy="4.899477e-005" iyz="0.0" izz="9.65717e-006"/>
    </inertial>
    <visual>
      <origin rpy="0 0 0" xyz="0 0 0"/>
      <geometry>
        <mesh filename="package://rb1_arm_description/meshes/arms/armRB1_67_link.dae"/>
      </geometry>
      <material name="darkgrey">
        <color rgba="0.1 0.1 0.1 1"/>
      </material>
    </visual>
    <collision>
      <origin rpy="0 0 0 " xyz="0 0 0"/>
      <geometry>
        <mesh filename="package://rb1_arm_description/meshes/arms/armRB1_67_link.dae"/>
      </geometry>
    </collision>
  </link>
  <link name="motor67_rb1_arm">
    <inertial>
      <mass value="0.34"/>
      <origin xyz="-0.01895 -0.00019 0"/>
      <inertia ixx="9.300873e-005" ixy="2.3781e-006" ixz="0.0" iyy="0.0002196171" iyz="0.0" izz="0.0002200183"/>
    </inertial>
    <visual>
      <origin rpy="0 0 0" xyz="0 0 0"/>
      <geometry>
        <mesh filename="package://rb1_arm_description/meshes/arms/armRB1_67_motor.dae"/>
      </geometry>
      <material name="darkgrey">
        <color rgba="0.1 0.1 0.1 1"/>
      </material>
    </visual>
    <collision>
      <origin rpy="0 0 0 " xyz="0 0 0"/>
      <geometry>
        <mesh filename="package://rb1_arm_description/meshes/arms/armRB1_67_motor.dae"/>
      </geometry>
    </collision>
  </link>
  <joint name="j67m_rb1_arm" type="fixed">
    <origin rpy="0.0 0.0 0.0" xyz="0.0 0.0 0.0"/>
    <parent link="link67_rb1_arm"/>
    <child link="motor67_rb1_arm"/>
    <axis xyz="0 0 0"/>
  </joint>
  <joint name="j6" type="revolute">
    <origin rpy="0.0 0.0 0.0" xyz="0 0 0"/>
    <parent link="link56_rb1_arm"/>
    <child link="link67_rb1_arm"/>
    <axis xyz="0 0 1"/>
    <limit effort="8.0" lower="-1.57" upper="1.57" velocity="2.98452"/>
    <dynamics damping="0.7" friction="0.5"/>
  </joint>
  <transmission name="j6_trans">
    <type>transmission_interface/SimpleTransmission</type>
    <joint name="j6">
      <hardwareInterface>EffortJointInterface</hardwareInterface>
    </joint>
    <actuator name="j6_motor">
      <mechanicalReduction>304.0</mechanicalReduction>
      <motorTorqueConstant>3.0</motorTorqueConstant>
    </actuator>
  </transmission>
  <!-- JOINT 7 -->
  <joint name="j7" type="revolute">
    <origin rpy="1.5708 0.0 0.0" xyz="0 0 0"/>
    <parent link="link67_rb1_arm"/>
    <child link="end_effector_rb1_arm"/>
    <axis xyz="1 0 0"/>
    <limit effort="8.0" lower="-3.13" upper="3.13" velocity="2.98452"/>
    <dynamics damping="0.7" friction="0.5"/>
  </joint>
  <transmission name="j7_trans">
    <type>transmission_interface/SimpleTransmission</type>
    <joint name="j7">
      <hardwareInterface>EffortJointInterface</hardwareInterface>
    </joint>
    <actuator name="j7_motor">
      <mechanicalReduction>304.0</mechanicalReduction>
      <motorTorqueConstant>3.0</motorTorqueConstant>
    </actuator>
  </transmission>
  <link name="end_effector_rb1_arm">	    
    </link>
  <!-- Gazebo ros control plugins -->
  <!-- xacro:ros_control/ -->
  <!-- Gazebo ros control plugins -->
  <!-- xacro:ros_control/ -->
  <!-- gazebo>
      <plugin name="ros_control" filename="libgazebo_ros_control.so">		
        <robotNamespace>/rb1</robotNamespace>
        <robotParam>robot_description</robotParam>
        <controlPeriod>0.001</controlPeriod> 
	    <robotSimType>gazebo_ros_control/DefaultRobotHWSim</robotSimType>
      </plugin>
    </gazebo -->
  <!-- Fix torso to base -->
  <joint name="j_base_torso" type="fixed">
    <origin rpy="0.0 0.0 0.0" xyz="0.0 0.0 0.0"/>
    <parent link="base_link"/>
    <child link="base_link_rb1_torso"/>
    <axis xyz="0 0 0"/>
  </joint>
  <!-- Fix arm to torso -->
  <joint name="j_torso_arm" type="fixed">
    <origin rpy="0.0 0.0 0.0" xyz="0.074 0.0 0.668"/>
    <parent link="link2_torso"/>
    <child link="base_link_rb1_arm"/>
    <axis xyz="0 0 0"/>
  </joint>
</robot>

