<?xml version="1.0" ?>
<!-- =================================================================================== -->
<!-- |    This document was autogenerated by xacro from rb1_robot_mico_3fg.urdf.xacro  | -->
<!-- |    EDITING THIS FILE BY HAND IS NOT RECOMMENDED                                 | -->
<!-- =================================================================================== -->
<robot name="rb1" xmlns:xacro="http://ros.org/wiki/xacro">
  <!-- ***************** -->
  <!-- Global parameters -->
  <!-- ***************** -->
  <!-- Flag to select the high or low quality model -->
  <!-- ***************** -->
  <!-- Imported elements -->
  <!-- ***************** -->
  <!-- First we import all posible elements defined in the urdf.xacro files. All these elements are defined as macro:xacros -->
  <!-- Import RB1 base -->
  <!-- ***************** -->
  <!-- Imported elements -->
  <!-- ***************** -->
  <!-- First we import all posible elements defined in the urdf.xacro files. All these elements are defined as macro:xacros -->
  <!-- Import RB1 base elements -->
  <!-- ros control plugin -->
  <!-- xacro:macro name="ros_control">
    <gazebo>
      <plugin name="ros_control" filename="libgazebo_ros_control.so">		
        <robotNamespace>/rb1</robotNamespace>
        <robotParam>robot_description</robotParam>
        <controlPeriod>0.001</controlPeriod> 
	    <robotSimType>gazebo_ros_control/DefaultRobotHWSim</robotSimType>
      </plugin>
    </gazebo>
	</xacro:macro -->
  <!-- differential drive plugin -->
  <gazebo reference="base_footprint">
    <material>Gazebo/Green</material>
  </gazebo>
  <!-- Import RB1 wheels -->
  <!-- Wheels -->
  <!-- in kg-->
  <!-- Wheels -->
  <!-- in kg-->
  <!-- Import all available sensors -->
  <!-- This file unifies all sensors that can be used on simulation, defined as xacro:macros -->
  <!-- Axis p5512 -->
  <!-- Axis m5013 -->
  <!-- Fotonic -->
  <!-- GPS -->
  <!-- Hokuyo urg04lx -->
  <!-- Hokuyo utm30lx -->
  <!-- Hokuyo ust10lx -->
  <!-- Imu -->
  <!-- Kinect -->
  <!-- Asus Xtion PRO -->
  <!-- Xacro properties -->
  <!-- xacro:property name="M_SCALE" value="0.001"/ -->
  z
  
  <!-- Hokuyo 3d -->
  <!-- Sick s3000 -->
  <!-- KinectV2 -->
  <!-- Orbbec Astra -->
  <!-- Xacro properties -->
  <!-- RGB sensor - cam -->
  <!-- IR sensor - depth -->
  <!-- ***************** -->
  <!-- Global parameters -->
  <!-- ***************** -->
  <!-- Wheel parameters -->
  <!-- x,y,z in translation from base_link to the center of the wheel -->
  <!-- Castor paramters -->
  <!-- Flag to select the high or low quality model -->
  <!-- *************** -->
  <!-- Robots Elements -->
  <!-- *************** -->
  <!-- Here we create the robot elements using the xacro:macros imported at the beggining of this file -->
  <!-- RB-1 base -->
  <!-- Robot mechanical and motor parameters -->
  <xacro:property name="PI" value="3.1415926535897931"/>
  <xacro:property name="wheel_width" value="0.175"/>
  <!-- BASE FOOTPRINT -->
  <link name="base_footprint">
    <visual>
      <origin rpy="0 0 0" xyz="0 0 0"/>
      <geometry>
        <box size="0.001 0.001 0.001"/>
      </geometry>
    </visual>
  </link>
  <joint name="base_footprint_joint" type="fixed">
    <origin rpy="0 0 0" xyz="0 0 0.025"/>
    <parent link="base_footprint"/>
    <child link="base_link"/>
  </joint>
  <!-- BASE_LINK -->
  <link name="base_link">
    <inertial>
      <mass value="25.0"/>
      <origin xyz="0 0 0"/>
      <inertia ixx="0.007" ixy="0.0" ixz="0.0" iyy="0.007" iyz="0.0" izz="0.78"/>
    </inertial>
    <visual>
      <origin rpy="0 0 0" xyz="0 0 0"/>
      <geometry>
        <mesh filename="package://rb1_base_description/meshes/bases/rb1v2_base.dae"/>
      </geometry>
      <material name="darkgrey">
        <color rgba="0.1 0.1 0.1 1"/>
      </material>
    </visual>
    <collision>
      <origin rpy="0 0 0 " xyz="0 0 0"/>
      <geometry>
        <mesh filename="package://rb1_base_description/meshes/bases/rb1v2_base.dae"/>
      </geometry>
    </collision>
  </link>
  <joint name="front_cover_joint" type="fixed">
    <origin rpy="0 0 0 " xyz="0.220 0.0 0.004"/>
    <parent link="base_link"/>
    <child link="front_cover_link"/>
  </joint>
  <!-- FRONT COVER -->
  <link name="front_cover_link">
    <inertial>
      <mass value="0.25"/>
      <origin xyz="0 0 0"/>
      <inertia ixx="0.00007" ixy="0.0" ixz="0.0" iyy="0.00007" iyz="0.0" izz="0.0078"/>
    </inertial>
    <visual>
      <origin rpy="0 0 0" xyz="0 0 0"/>
      <geometry>
        <mesh filename="package://rb1_base_description/meshes/bases/rb1v2_front_cover.dae"/>
      </geometry>
      <material name="black">
        <color rgba="0.0 0.0 0.0 1"/>
      </material>
    </visual>
    <collision>
      <origin rpy="0 0 0 " xyz="0 0 0"/>
      <geometry>
        <mesh filename="package://rb1_base_description/meshes/bases/rb1v2_front_cover.dae"/>
      </geometry>
    </collision>
  </link>
  <!-- Gazebo ros control plugins -->
  <gazebo>
    <plugin filename="libgazebo_ros_control.so" name="ros_control">
      <!-- robotNamespace>mico</robotNamespace -->
      <robotNamespace>rb1</robotNamespace>
      <robotParam>robot_description</robotParam>
      <controlPeriod>0.001</controlPeriod>
      <robotSimType>gazebo_ros_control/DefaultRobotHWSim</robotSimType>
    </plugin>
  </gazebo>
  <gazebo reference="mico_link_base">
    <material>Gazebo/FlatBlack</material>
    <turnGravityOff>true</turnGravityOff>
  </gazebo>
  <gazebo reference="mico_link_1">
    <material>Gazebo/FlatBlack</material>
    <turnGravityOff>true</turnGravityOff>
  </gazebo>
  <gazebo reference="mico_link_2">
    <material>Gazebo/FlatBlack</material>
    <turnGravityOff>true</turnGravityOff>
  </gazebo>
  <gazebo reference="mico_link_3">
    <material>Gazebo/FlatBlack</material>
    <turnGravityOff>true</turnGravityOff>
  </gazebo>
  <gazebo reference="mico_link_4">
    <material>Gazebo/FlatBlack</material>
    <turnGravityOff>true</turnGravityOff>
  </gazebo>
  <gazebo reference="mico_link_5">
    <material>Gazebo/FlatBlack</material>
    <turnGravityOff>true</turnGravityOff>
  </gazebo>
  <gazebo reference="mico_link_hand">
    <material>Gazebo/FlatBlack</material>
    <turnGravityOff>true</turnGravityOff>
  </gazebo>
  <gazebo reference="mico_link_finger_1">
    <material>Gazebo/Grey</material>
    <turnGravityOff>true</turnGravityOff>
  </gazebo>
  <gazebo reference="mico_link_finger_2">
    <material>Gazebo/Grey</material>
    <turnGravityOff>true</turnGravityOff>
  </gazebo>
  <!-- Gazebo skid steering plugins -->
  <gazebo>
    <plugin filename="libgazebo_ros_diff_drive.so" name="differential_drive_controller">
      <alwaysOn>true</alwaysOn>
      <updateRate>50.0</updateRate>
      <!-- leftJoint>joint_left_wheel</leftJoint>
        <rightJoint>joint_right_wheel</rightJoint -->
      <leftJoint>joint_right_wheel</leftJoint>
      <rightJoint>joint_left_wheel</rightJoint>
      <!-- For V0 0.365 -->
      <!-- wheelSeparation>0.365</wheelSeparation -->
      <wheelSeparation>0.433</wheelSeparation>
      <wheelDiameter>0.1524</wheelDiameter>
      <commandTopic>/rb1/cmd_vel</commandTopic>
      <odometryTopic>odom</odometryTopic>
      <odometryFrame>odom</odometryFrame>
      <robotBaseFrame>base_footprint</robotBaseFrame>
      <!-- robotNamespace></robotNamespace -->
      <rosDebugLevel>na</rosDebugLevel>
      <publishWheelTF>false</publishWheelTF>
      <publishWheelJointState>false</publishWheelJointState>
      <wheelAcceleration>0</wheelAcceleration>
      <wheelTorque>5</wheelTorque>
      <!-- odometrySource>encoder</odometrySource -->
      <odometrySource>world</odometrySource>
      <publishTf>1</publishTf>
    </plugin>
  </gazebo>
  <!-- WHEELS -->
  <!--WHEEL TIRE -->
  <joint name="joint_right_wheel" type="continuous">
    <parent link="base_link"/>
    <child link="right_wheel"/>
    <origin rpy="0 0 0" xyz="0.0 -0.217 0.051"/>
    <axis rpy="0 0 0" xyz="0 1 0"/>
    <limit effort="100" velocity="100"/>
    <joint_properties damping="0.0" friction="0.0"/>
  </joint>
  <link name="right_wheel">
    <visual>
      <!-- HIGH RESOLUTION WHEELS -->
      <origin rpy="0 0 0" xyz="0 0 0"/>
      <geometry>
        <mesh filename="package://rb1_base_description/meshes/wheels/wheel_rubber_6inch.dae"/>
      </geometry>
      <!-- LOW RESOLUTION WHEELS -->
    </visual>
    <collision>
      <origin rpy="1.57079632679 0 0" xyz="0 0 0"/>
      <geometry>
        <cylinder length="0.025" radius="0.076"/>
      </geometry>
    </collision>
    <inertial>
      <mass value="1.0"/>
      <origin xyz="0 0 0"/>
      <inertia ixx="0.00149608333333" ixy="0" ixz="0" iyy="0.00149608333333" iyz="0" izz="0.002888"/>
    </inertial>
  </link>
  <!-- Transmission is important to link the joints and the controller (see rb1_control/config/rb1_control.yaml)-->
  <transmission name="right_wheel_joint_trans">
    <type>transmission_interface/SimpleTransmission</type>
    <joint name="joint_right_wheel">
      <hardwareInterface>EffortJointInterface</hardwareInterface>
    </joint>
    <actuator name="right_wheel_joint_motor">
      <!-- hardwareInterface>EffortJointInterface</hardwareInterface -->
      <mechanicalReduction>1</mechanicalReduction>
      <motorTorqueConstant>10</motorTorqueConstant>
    </actuator>
  </transmission>
  <gazebo reference="right_wheel">
    <mu1 value="5.0"/>
    <mu2 value="0.5"/>
    <kp value="10000000.0"/>
    <kd value="1.0"/>
    <fdir1 value="1 0 0"/>
    <turnGravityOff>false</turnGravityOff>
  </gazebo>
  <!--WHEEL TIRE -->
  <joint name="joint_left_wheel" type="continuous">
    <parent link="base_link"/>
    <child link="left_wheel"/>
    <origin rpy="0 0 0" xyz="0.0 0.217 0.051"/>
    <axis rpy="0 0 0" xyz="0 1 0"/>
    <limit effort="100" velocity="100"/>
    <joint_properties damping="0.0" friction="0.0"/>
  </joint>
  <link name="left_wheel">
    <visual>
      <!-- HIGH RESOLUTION WHEELS -->
      <origin rpy="0 0 0" xyz="0 0 0"/>
      <geometry>
        <mesh filename="package://rb1_base_description/meshes/wheels/wheel_rubber_6inch.dae"/>
      </geometry>
      <!-- LOW RESOLUTION WHEELS -->
    </visual>
    <collision>
      <origin rpy="1.57079632679 0 0" xyz="0 0 0"/>
      <geometry>
        <cylinder length="0.025" radius="0.076"/>
      </geometry>
    </collision>
    <inertial>
      <mass value="1.0"/>
      <origin xyz="0 0 0"/>
      <inertia ixx="0.00149608333333" ixy="0" ixz="0" iyy="0.00149608333333" iyz="0" izz="0.002888"/>
    </inertial>
  </link>
  <!-- Transmission is important to link the joints and the controller (see rb1_control/config/rb1_control.yaml)-->
  <transmission name="left_wheel_joint_trans">
    <type>transmission_interface/SimpleTransmission</type>
    <joint name="joint_left_wheel">
      <hardwareInterface>EffortJointInterface</hardwareInterface>
    </joint>
    <actuator name="left_wheel_joint_motor">
      <!-- hardwareInterface>EffortJointInterface</hardwareInterface -->
      <mechanicalReduction>1</mechanicalReduction>
      <motorTorqueConstant>10</motorTorqueConstant>
    </actuator>
  </transmission>
  <gazebo reference="left_wheel">
    <mu1 value="5.0"/>
    <mu2 value="0.5"/>
    <kp value="10000000.0"/>
    <kd value="1.0"/>
    <fdir1 value="1 0 0"/>
    <turnGravityOff>false</turnGravityOff>
  </gazebo>
  <!-- OMNI DIRECTIONAL WHEELS -->
  <!--WHEEL TIRE -->
  <!-- joint name="joint_${name}_wheel" type="continuous" -->
  <joint name="joint_omni_back_wheel" type="fixed">
    <parent link="base_link"/>
    <child link="omni_back_wheel"/>
    <origin rpy="0 0 0" xyz="-0.195 0.0 0.0265"/>
    <axis rpy="0 0 0" xyz="0 1 0"/>
    <limit effort="100" velocity="100"/>
    <joint_properties damping="0.0" friction="0.0"/>
  </joint>
  <link name="omni_back_wheel">
    <visual>
      <!-- HIGH RESOLUTION WHEELS -->
      <origin rpy="0 0 0" xyz="0 0 0"/>
      <geometry>
        <mesh filename="package://rb1_base_description/meshes/wheels/rb1v2_omniwheel.dae"/>
      </geometry>
      <!-- LOW RESOLUTION WHEELS -->
    </visual>
    <!-- collision>
      <origin xyz="0 0 0" rpy="${M_PI/2} 0 0" />
        <geometry>
          <cylinder length="${omni_wheel_height}" radius="${omni_wheel_radius}" />
        </geometry>
      </collision -->
    <collision>
      <origin rpy="1.57079632679 0 0" xyz="0 0 0"/>
      <geometry>
        <sphere radius="0.051"/>
      </geometry>
    </collision>
    <inertial>
      <mass value="1.0"/>
      <origin xyz="0 0 0"/>
      <inertia ixx="0.000235075" ixy="0" ixz="0" iyy="0.000235075" iyz="0" izz="0.00039015"/>
      <!-- inertia  ixx="0.001" ixy="0.0"  ixz="0.0"  iyy="0.001"  iyz="0.0"  izz="0.001" / -->
    </inertial>
  </link>
  <!-- transmission name="${name}_wheel_joint_trans">
      <type>transmission_interface/SimpleTransmission</type>
      <joint name="joint_${name}_wheel" />
      <actuator name="${name}_wheel_joint_motor">
        <hardwareInterface>EffortJointInterface</hardwareInterface>
        <mechanicalReduction>1</mechanicalReduction>
      </actuator>
    </transmission -->
  <gazebo reference="omni_back_wheel">
    <mu1 value="0.0"/>
    <mu2 value="0.0"/>
    <kp value="10000000.0"/>
    <kd value="1.0"/>
    <fdir1 value="1 0 0"/>
    <turnGravityOff>false</turnGravityOff>
  </gazebo>
  <!--WHEEL TIRE -->
  <!-- joint name="joint_${name}_wheel" type="continuous" -->
  <joint name="joint_omni_front_left_wheel" type="fixed">
    <parent link="base_link"/>
    <child link="omni_front_left_wheel"/>
    <origin rpy="0 0 0" xyz="0.133 0.148 0.0265"/>
    <axis rpy="0 0 0" xyz="0 1 0"/>
    <limit effort="100" velocity="100"/>
    <joint_properties damping="0.0" friction="0.0"/>
  </joint>
  <link name="omni_front_left_wheel">
    <visual>
      <!-- HIGH RESOLUTION WHEELS -->
      <origin rpy="0 0 0" xyz="0 0 0"/>
      <geometry>
        <mesh filename="package://rb1_base_description/meshes/wheels/rb1v2_omniwheel.dae"/>
      </geometry>
      <!-- LOW RESOLUTION WHEELS -->
    </visual>
    <!-- collision>
      <origin xyz="0 0 0" rpy="${M_PI/2} 0 0" />
        <geometry>
          <cylinder length="${omni_wheel_height}" radius="${omni_wheel_radius}" />
        </geometry>
      </collision -->
    <collision>
      <origin rpy="1.57079632679 0 0" xyz="0 0 0"/>
      <geometry>
        <sphere radius="0.051"/>
      </geometry>
    </collision>
    <inertial>
      <mass value="1.0"/>
      <origin xyz="0 0 0"/>
      <inertia ixx="0.000235075" ixy="0" ixz="0" iyy="0.000235075" iyz="0" izz="0.00039015"/>
      <!-- inertia  ixx="0.001" ixy="0.0"  ixz="0.0"  iyy="0.001"  iyz="0.0"  izz="0.001" / -->
    </inertial>
  </link>
  <!-- transmission name="${name}_wheel_joint_trans">
      <type>transmission_interface/SimpleTransmission</type>
      <joint name="joint_${name}_wheel" />
      <actuator name="${name}_wheel_joint_motor">
        <hardwareInterface>EffortJointInterface</hardwareInterface>
        <mechanicalReduction>1</mechanicalReduction>
      </actuator>
    </transmission -->
  <gazebo reference="omni_front_left_wheel">
    <mu1 value="0.0"/>
    <mu2 value="0.0"/>
    <kp value="10000000.0"/>
    <kd value="1.0"/>
    <fdir1 value="1 0 0"/>
    <turnGravityOff>false</turnGravityOff>
  </gazebo>
  <!--WHEEL TIRE -->
  <!-- joint name="joint_${name}_wheel" type="continuous" -->
  <joint name="joint_omni_front_right_wheel" type="fixed">
    <parent link="base_link"/>
    <child link="omni_front_right_wheel"/>
    <origin rpy="0 0 0" xyz="0.133 -0.148 0.0265"/>
    <axis rpy="0 0 0" xyz="0 1 0"/>
    <limit effort="100" velocity="100"/>
    <joint_properties damping="0.0" friction="0.0"/>
  </joint>
  <link name="omni_front_right_wheel">
    <visual>
      <!-- HIGH RESOLUTION WHEELS -->
      <origin rpy="0 0 0" xyz="0 0 0"/>
      <geometry>
        <mesh filename="package://rb1_base_description/meshes/wheels/rb1v2_omniwheel.dae"/>
      </geometry>
      <!-- LOW RESOLUTION WHEELS -->
    </visual>
    <!-- collision>
      <origin xyz="0 0 0" rpy="${M_PI/2} 0 0" />
        <geometry>
          <cylinder length="${omni_wheel_height}" radius="${omni_wheel_radius}" />
        </geometry>
      </collision -->
    <collision>
      <origin rpy="1.57079632679 0 0" xyz="0 0 0"/>
      <geometry>
        <sphere radius="0.051"/>
      </geometry>
    </collision>
    <inertial>
      <mass value="1.0"/>
      <origin xyz="0 0 0"/>
      <inertia ixx="0.000235075" ixy="0" ixz="0" iyy="0.000235075" iyz="0" izz="0.00039015"/>
      <!-- inertia  ixx="0.001" ixy="0.0"  ixz="0.0"  iyy="0.001"  iyz="0.0"  izz="0.001" / -->
    </inertial>
  </link>
  <!-- transmission name="${name}_wheel_joint_trans">
      <type>transmission_interface/SimpleTransmission</type>
      <joint name="joint_${name}_wheel" />
      <actuator name="${name}_wheel_joint_motor">
        <hardwareInterface>EffortJointInterface</hardwareInterface>
        <mechanicalReduction>1</mechanicalReduction>
      </actuator>
    </transmission -->
  <gazebo reference="omni_front_right_wheel">
    <mu1 value="0.0"/>
    <mu2 value="0.0"/>
    <kp value="10000000.0"/>
    <kd value="1.0"/>
    <fdir1 value="1 0 0"/>
    <turnGravityOff>false</turnGravityOff>
  </gazebo>
  <!-- SENSORS -->
  <!-- xacro:sensor_hokuyo_utm30lx name="hokuyo" parent="base_link">
		<origin xyz="0.210 0.0 0.305" rpy="0 0 0"/>
	</xacro:sensor_hokuyo_utm30lx -->
  <!-- xacro:sensor_hokuyo_urg04lx name="hokuyo" parent="base_link">
        <origin xyz="0.223 0.0 0.209" rpy="0 3.1416 3.1416"/>
    </xacro:sensor_hokuyo_urg04lx -->
  <joint name="hokuyo_laser_joint" type="fixed">
    <origin rpy="0 3.1416 3.1416" xyz="0.223 0.0 0.159"/>
    <parent link="base_link"/>
    <child link="hokuyo_laser_link"/>
  </joint>
  <link name="hokuyo_laser_link">
    <collision>
      <origin rpy="0 0 0" xyz="0 0 -0.05"/>
      <geometry>
        <box size="0.010 0.010 0.010"/>
      </geometry>
    </collision>
    <visual>
      <origin rpy="0 0 0" xyz="0 0 -0.05"/>
      <geometry>
        <mesh filename="package://robotnik_sensors/meshes/hokuyo_ust_10lx.dae"/>
      </geometry>
    </visual>
    <inertial>
      <mass value="1e-5"/>
      <origin rpy="0 0 0" xyz="0 0 0"/>
      <inertia ixx="1e-6" ixy="0" ixz="0" iyy="1e-6" iyz="0" izz="1e-6"/>
    </inertial>
  </link>
  <!-- Hokuyo sensor for simulation -->
  <gazebo reference="hokuyo_laser_link">
    <sensor name="hokuyo_sensor" type="ray">
      <pose>0 0 0 0 0 0</pose>
      <visualize>false</visualize>
      <update_rate>40</update_rate>
      <ray>
        <scan>
          <horizontal>
            <samples>1081</samples>
            <resolution>1</resolution>
            <min_angle>2.3562</min_angle>
            <max_angle>-2.3562</max_angle>
          </horizontal>
        </scan>
        <range>
          <min>0.06</min>
          <max>20.0</max>
          <!-- resolution>0.004363323</resolution -->
          <resolution>0.004359297</resolution>
          <!-- resolution>0.001</resolution -->
        </range>
        <noise>
          <type>gaussian</type>
          <mean>0.0</mean>
          <stddev>0.01</stddev>
        </noise>
      </ray>
      <plugin filename="libgazebo_ros_laser.so" name="gazebo_ros_head_hokuyo_controller">
        <topicName>hokuyo/scan</topicName>
        <frameName>hokuyo_laser_link</frameName>
      </plugin>
    </sensor>
  </gazebo>
  <joint name="imu_joint" type="fixed">
    <axis xyz="1 0 0"/>
    <!--origin xyz="0 0 0.2825"/-->
    <origin rpy="0 0 0" xyz="-0.18 0.0 0.170"/>
    <parent link="base_link"/>
    <child link="imu_link"/>
  </joint>
  <link name="imu_link">
    <inertial>
      <mass value="0.001"/>
      <origin rpy="0 0 0" xyz="0 0 0"/>
      <inertia ixx="0.0001" ixy="0" ixz="0" iyy="0.000001" iyz="0" izz="0.0001"/>
    </inertial>
    <visual>
      <origin rpy="0 0 0" xyz="0 0 0"/>
      <geometry>
        <box size="0.001 0.001 0.001"/>
      </geometry>
    </visual>
    <collision>
      <origin rpy="0 0 0" xyz="0 0 0"/>
      <geometry>
        <box size=".001 .001 .001"/>
      </geometry>
    </collision>
  </link>
  <gazebo>
    <plugin filename="libgazebo_ros_imu.so" name="ros_imu">
      <topicName>imu_data</topicName>
      <bodyName>imu_link</bodyName>
      <serviceName>imu_service</serviceName>
      <gaussianNoise>0.005</gaussianNoise>
    </plugin>
  </gazebo>
  <joint name="orbbec_astra_cam_rgb_joint" type="fixed">
    <origin rpy="0 0 0" xyz="0.234 0.0125 0.107"/>
    <parent link="base_link"/>
    <child link="orbbec_astra_cam_rgb_frame"/>
  </joint>
  <link name="orbbec_astra_cam_rgb_frame">
    <inertial>
      <mass value="0.001"/>
      <origin xyz="0 0 0"/>
      <inertia ixx="0.0001" ixy="0.0" ixz="0.0" iyy="0.0001" iyz="0.0" izz="0.0001"/>
    </inertial>
  </link>
  <joint name="orbbec_astra_cam_rgb_optical_joint" type="fixed">
    <origin rpy="-1.57079632679 0 -1.57079632679" xyz="0.0 0.0 0.0"/>
    <parent link="orbbec_astra_cam_rgb_frame"/>
    <child link="orbbec_astra_cam_rgb_optical_frame"/>
  </joint>
  <link name="orbbec_astra_cam_rgb_optical_frame">
    <inertial>
      <mass value="0.001"/>
      <origin xyz="0 0 0"/>
      <inertia ixx="0.0001" ixy="0.0" ixz="0.0" iyy="0.0001" iyz="0.0" izz="0.0001"/>
    </inertial>
  </link>
  <joint name="orbbec_astra_cam_joint" type="fixed">
    <origin rpy="0 0 0" xyz="0.0 -0.0125 -0.015"/>
    <parent link="orbbec_astra_cam_rgb_frame"/>
    <child link="orbbec_astra_cam_link"/>
  </joint>
  <link name="orbbec_astra_cam_link">
    <visual>
      <origin rpy="0 0 0" xyz="0 0 0"/>
      <geometry>
        <mesh filename="package://robotnik_sensors/meshes/orbbec_astra.dae" scale="1.0 1.0 1.0"/>
      </geometry>
    </visual>
    <collision>
      <origin rpy="0 0 0" xyz="0.0 0.0 0.0"/>
      <geometry>
        <box size="0.0730 .2760 0.0720"/>
      </geometry>
    </collision>
    <inertial>
      <mass value="0.01"/>
      <origin xyz="0 0 0"/>
      <inertia ixx="0.001" ixy="0.0" ixz="0.0" iyy="0.001" iyz="0.0" izz="0.001"/>
    </inertial>
  </link>
  <joint name="orbbec_astra_cam_depth_joint" type="fixed">
    <origin rpy="0 0 0" xyz="0.0 0.025 0.0"/>
    <parent link="orbbec_astra_cam_rgb_frame"/>
    <child link="orbbec_astra_cam_depth_frame"/>
  </joint>
  <link name="orbbec_astra_cam_depth_frame">
    <inertial>
      <mass value="0.01"/>
      <origin xyz="0 0 0"/>
      <inertia ixx="0.001" ixy="0.0" ixz="0.0" iyy="0.001" iyz="0.0" izz="0.001"/>
    </inertial>
  </link>
  <joint name="orbbec_astra_cam_depth_optical_joint" type="fixed">
    <origin rpy="-1.57079632679 0 -1.57079632679" xyz="0 0 0"/>
    <parent link="orbbec_astra_cam_depth_frame"/>
    <child link="orbbec_astra_cam_depth_optical_frame"/>
  </joint>
  <link name="orbbec_astra_cam_depth_optical_frame">
    <inertial>
      <mass value="0.001"/>
      <origin xyz="0 0 0"/>
      <inertia ixx="0.0001" ixy="0.0" ixz="0.0" iyy="0.0001" iyz="0.0" izz="0.0001"/>
    </inertial>
  </link>
  <!-- RGBD sensor for simulation, same as Kinect -->
  <gazebo reference="orbbec_astra_cam_depth_frame">
    <sensor name="cam" type="depth">
      <always_on>true</always_on>
      <update_rate>20.0</update_rate>
      <camera>
        <horizontal_fov>1.0471975512</horizontal_fov>
        <image>
          <format>R8G8B8</format>
          <width>640</width>
          <height>480</height>
        </image>
        <clip>
          <near>0.05</near>
          <far>3.5</far>
        </clip>
      </camera>
      <plugin filename="libgazebo_ros_openni_kinect.so" name="xtion_pro_cam_controller">
        <cameraName>orbbec_astra</cameraName>
        <alwaysOn>true</alwaysOn>
        <updateRate>15</updateRate>
        <imageTopicName>rgb/image_raw</imageTopicName>
        <depthImageTopicName>depth/image_raw</depthImageTopicName>
        <pointCloudTopicName>depth/points</pointCloudTopicName>
        <cameraInfoTopicName>rgb/camera_info</cameraInfoTopicName>
        <depthImageCameraInfoTopicName>depth/camera_info</depthImageCameraInfoTopicName>
        <frameName>orbbec_astra_cam_depth_optical_frame</frameName>
        <baseline>0.1</baseline>
        <distortion_k1>0.0</distortion_k1>
        <distortion_k2>0.0</distortion_k2>
        <distortion_k3>0.0</distortion_k3>
        <distortion_t1>0.0</distortion_t1>
        <distortion_t2>0.0</distortion_t2>
        <pointCloudCutoff>0.4</pointCloudCutoff>
      </plugin>
    </sensor>
  </gazebo>
  <!--
    <xacro:sensor_kinect name="kinect" parent="base_link">
        <origin xyz="0.3 0.0 0.16" rpy="0 0 0"/> 
    </xacro:sensor_kinect>  
-->
  <!-- Import RB1 torso -->
  <!-- ***************** -->
  <!-- Imported elements -->
  <!-- ***************** -->
  <!-- First we import all posible elements defined in the urdf.xacro files. All these elements are defined as macro:xacros -->
  <!-- Import RB1 arm elements -->
  <!-- xacro:include filename="$(find rb1_torso_description)/urdf/rb1_torso_3dof.gazebo.xacro" / -->
  <!-- Import all available sensors -->
  <!-- This file unifies all sensors that can be used on simulation, defined as xacro:macros -->
  <!-- Axis p5512 -->
  <!-- Axis m5013 -->
  <!-- Fotonic -->
  <!-- GPS -->
  <!-- Hokuyo urg04lx -->
  <!-- Hokuyo utm30lx -->
  <!-- Hokuyo ust10lx -->
  <!-- Imu -->
  <!-- Kinect -->
  <!-- Asus Xtion PRO -->
  <!-- Xacro properties -->
  <!-- xacro:property name="M_SCALE" value="0.001"/ -->
  z
  
  <!-- Hokuyo 3d -->
  <!-- Sick s3000 -->
  <!-- KinectV2 -->
  <!-- Orbbec Astra -->
  <!-- Xacro properties -->
  <!-- RGB sensor - cam -->
  <!-- IR sensor - depth -->
  <!-- ***************** -->
  <!-- Global parameters -->
  <!-- ***************** -->
  <!-- Flag to select the high or low quality model -->
  <!-- RB-1 torso -->
  <!-- Robot mechanical and motor parameters -->
  <xacro:property name="PI" value="3.1415926535897931"/>
  <!-- BASE_LINK -->
  <link name="base_link_rb1_torso">
  </link>
  <link name="link1_torso">
    <inertial>
      <mass value="3.0"/>
      <origin xyz="0 0 0"/>
      <inertia ixx="1.0" ixy="0.0" ixz="0.0" iyy="1.0" iyz="0.0" izz="1.0"/>
    </inertial>
    <visual>
      <origin rpy="0 0 0" xyz="0 0 0"/>
      <geometry>
        <mesh filename="package://rb1_torso_description/meshes/torsos/rb1v2_superior1.dae"/>
      </geometry>
      <material name="darkgrey">
        <color rgba="0.1 0.1 0.1 1"/>
      </material>
    </visual>
    <collision>
      <origin rpy="0 0 0 " xyz="0 0 0"/>
      <geometry>
        <mesh filename="package://rb1_torso_description/meshes/torsos/rb1v2_superior1.dae"/>
      </geometry>
    </collision>
  </link>
  <joint name="j0_rb1_torso" type="fixed">
    <origin rpy="0.0 0.0 0.0" xyz="0.0 0.0 0.0"/>
    <parent link="base_link_rb1_torso"/>
    <child link="link1_torso"/>
    <axis xyz="0 0 0"/>
  </joint>
  <link name="link1_guide">
    <inertial>
      <mass value="2.0"/>
      <origin xyz="0 0 0"/>
      <inertia ixx="1.0" ixy="0.0" ixz="0.0" iyy="1.0" iyz="0.0" izz="1.0"/>
    </inertial>
    <visual>
      <origin rpy="0 0 0" xyz="0 0 0"/>
      <geometry>
        <mesh filename="package://rb1_torso_description/meshes/torsos/rb1v2_guide.dae"/>
      </geometry>
      <material name="darkgrey">
        <color rgba="0.1 0.1 0.1 1"/>
      </material>
    </visual>
    <collision>
      <origin rpy="0 0 0 " xyz="0 0 0"/>
      <geometry>
        <mesh filename="package://rb1_torso_description/meshes/torsos/rb1v2_guide.dae"/>
      </geometry>
    </collision>
  </link>
  <joint name="j00_rb1_torso" type="fixed">
    <origin rpy="0.0 0.0 0.0" xyz="0.0 0.0 0.0"/>
    <parent link="link1_torso"/>
    <child link="link1_guide"/>
    <axis xyz="0 0 0"/>
  </joint>
  <link name="link2_torso">
    <inertial>
      <mass value="2.0"/>
      <origin xyz="0 0 0"/>
      <inertia ixx="1.0" ixy="0.0" ixz="0.0" iyy="1.0" iyz="0.0" izz="1.0"/>
    </inertial>
    <visual>
      <origin rpy="0 0 0" xyz="0 0 0"/>
      <geometry>
        <mesh filename="package://rb1_torso_description/meshes/torsos/rb1v2_superior2.dae"/>
      </geometry>
      <material name="darkgrey">
        <color rgba="0.1 0.1 0.1 1"/>
      </material>
    </visual>
    <collision>
      <origin rpy="0 0 0 " xyz="0 0 0"/>
      <geometry>
        <mesh filename="package://rb1_torso_description/meshes/torsos/rb1v2_superior2.dae"/>
      </geometry>
    </collision>
  </link>
  <joint name="j1_torso" type="prismatic">
    <!-- origin
      xyz="0.078 0 0.016" 
      rpy="0.0 0.0 0.0" / -->
    <origin rpy="0.0 0.0 0.0" xyz="0.078 0 0.091"/>
    <parent link="link1_torso"/>
    <child link="link2_torso"/>
    <axis xyz="0 0 1"/>
    <limit effort="5000.0" lower="0.0" upper="0.36" velocity="1.0"/>
    <dynamics damping="0.7" friction="0.5"/>
  </joint>
  <transmission name="j1_torso_trans">
    <type>transmission_interface/SimpleTransmission</type>
    <joint name="j1_torso">
      <hardwareInterface>EffortJointInterface</hardwareInterface>
    </joint>
    <actuator name="j1_torso_motor">
      <mechanicalReduction>320.0</mechanicalReduction>
      <motorTorqueConstant>1.0</motorTorqueConstant>
    </actuator>
  </transmission>
  <link name="link2_cover">
    <inertial>
      <mass value="1.0"/>
      <origin xyz="0 0 0"/>
      <inertia ixx="1.0" ixy="0.0" ixz="0.0" iyy="1.0" iyz="0.0" izz="1.0"/>
    </inertial>
    <visual>
      <origin rpy="0 0 0" xyz="0 0 0"/>
      <geometry>
        <mesh filename="package://rb1_torso_description/meshes/torsos/rb1v2_rear_cover.dae"/>
      </geometry>
      <material name="darkgrey">
        <color rgba="0.1 0.1 0.1 1"/>
      </material>
    </visual>
    <collision>
      <origin rpy="0 0 0 " xyz="0 0 0"/>
      <geometry>
        <mesh filename="package://rb1_torso_description/meshes/torsos/rb1v2_rear_cover.dae"/>
      </geometry>
    </collision>
  </link>
  <joint name="j11_rb1_torso" type="fixed">
    <!--origin
      xyz="-0.164 0.0 0.064"
      rpy="0.0 0.0 0.0" / -->
    <origin rpy="0.0 0.0 0.0" xyz="-0.164 0.0 0.0"/>
    <parent link="link2_torso"/>
    <child link="link2_cover"/>
    <axis xyz="0 0 0"/>
  </joint>
  <link name="link1_head">
    <inertial>
      <mass value="1.0"/>
      <origin xyz="0 0 0"/>
      <inertia ixx="1.0" ixy="0.0" ixz="0.0" iyy="1.0" iyz="0.0" izz="1.0"/>
    </inertial>
    <visual>
      <origin rpy="0 0 0" xyz="0 0 0"/>
      <geometry>
        <mesh filename="package://rb1_torso_description/meshes/heads/rb1v2_head1.dae"/>
      </geometry>
      <material name="darkgrey">
        <color rgba="0.1 0.1 0.1 1"/>
      </material>
    </visual>
    <collision>
      <origin rpy="0 0 0 " xyz="0 0 0"/>
      <geometry>
        <mesh filename="package://rb1_torso_description/meshes/heads/rb1v2_head1.dae"/>
      </geometry>
    </collision>
  </link>
  <joint name="j1_head" type="revolute">
    <!-- origin
      xyz="0.055 0.0 0.686"
      rpy="0.0 0.0 0.0" / -->
    <origin rpy="0.0 0.0 0.0" xyz="0.055 0.0 0.621"/>
    <parent link="link2_torso"/>
    <child link="link1_head"/>
    <axis xyz="0 0 1"/>
    <limit effort="60.0" lower="-1.57079632679" upper="1.57079632679" velocity="2.9217"/>
    <dynamics damping="0.7" friction="0.5"/>
  </joint>
  <transmission name="j1_head_trans">
    <type>transmission_interface/SimpleTransmission</type>
    <joint name="j1_head">
      <hardwareInterface>EffortJointInterface</hardwareInterface>
    </joint>
    <actuator name="j1_head_motor">
      <mechanicalReduction>320.0</mechanicalReduction>
      <motorTorqueConstant>1.0</motorTorqueConstant>
    </actuator>
  </transmission>
  <link name="link2_head">
    <inertial>
      <mass value="1.0"/>
      <origin xyz="0 0 0"/>
      <inertia ixx="1.0" ixy="0.0" ixz="0.0" iyy="1.0" iyz="0.0" izz="1.0"/>
    </inertial>
    <visual>
      <origin rpy="0 0 0" xyz="0 0 0"/>
      <geometry>
        <mesh filename="package://rb1_torso_description/meshes/heads/rb1v2_head2.dae"/>
      </geometry>
      <material name="darkgrey">
        <color rgba="0.1 0.1 0.1 1"/>
      </material>
    </visual>
    <collision>
      <origin rpy="0 0 0 " xyz="0 0 0"/>
      <geometry>
        <mesh filename="package://rb1_torso_description/meshes/heads/rb1v2_head2.dae"/>
      </geometry>
    </collision>
  </link>
  <joint name="j2_head" type="revolute">
    <origin rpy="0.0 0.0 0.0" xyz="0.081 0.0 0.0"/>
    <parent link="link1_head"/>
    <child link="link2_head"/>
    <!-- check -->
    <!-- axis xyz="0 1 0" / -->
    <axis xyz="0 -1 0"/>
    <limit effort="60.0" lower="-0.785398163397" upper="0.785398163397" velocity="2.9217"/>
    <dynamics damping="0.7" friction="0.5"/>
  </joint>
  <transmission name="j2_head_trans">
    <type>transmission_interface/SimpleTransmission</type>
    <joint name="j2_head">
      <hardwareInterface>EffortJointInterface</hardwareInterface>
    </joint>
    <actuator name="j2_head_motor">
      <mechanicalReduction>320.0</mechanicalReduction>
      <motorTorqueConstant>1.0</motorTorqueConstant>
    </actuator>
  </transmission>
  <!-- Ixtion sensor in head -->
  <!-- xacro:sensor_asus_xtion_pro name="xtion_head" parent="link2_head">		
        <origin xyz="0.055 0.000 0.028" rpy="0 0 0"/> 
    </xacro:sensor_asus_xtion_pro -->
  <!-- RGBD sensor -->
  <joint name="orbbec_astra_head_cam_rgb_joint" type="fixed">
    <origin rpy="0 0 0" xyz="0.055 0.0125 0.028"/>
    <parent link="link2_head"/>
    <child link="orbbec_astra_head_cam_rgb_frame"/>
  </joint>
  <link name="orbbec_astra_head_cam_rgb_frame">
    <inertial>
      <mass value="0.001"/>
      <origin xyz="0 0 0"/>
      <inertia ixx="0.0001" ixy="0.0" ixz="0.0" iyy="0.0001" iyz="0.0" izz="0.0001"/>
    </inertial>
  </link>
  <joint name="orbbec_astra_head_cam_rgb_optical_joint" type="fixed">
    <origin rpy="-1.57079632679 0 -1.57079632679" xyz="0.0 0.0 0.0"/>
    <parent link="orbbec_astra_head_cam_rgb_frame"/>
    <child link="orbbec_astra_head_cam_rgb_optical_frame"/>
  </joint>
  <link name="orbbec_astra_head_cam_rgb_optical_frame">
    <inertial>
      <mass value="0.001"/>
      <origin xyz="0 0 0"/>
      <inertia ixx="0.0001" ixy="0.0" ixz="0.0" iyy="0.0001" iyz="0.0" izz="0.0001"/>
    </inertial>
  </link>
  <joint name="orbbec_astra_head_cam_joint" type="fixed">
    <origin rpy="0 0 0" xyz="0.0 -0.0125 -0.015"/>
    <parent link="orbbec_astra_head_cam_rgb_frame"/>
    <child link="orbbec_astra_head_cam_link"/>
  </joint>
  <link name="orbbec_astra_head_cam_link">
    <visual>
      <origin rpy="0 0 0" xyz="0 0 0"/>
      <geometry>
        <mesh filename="package://robotnik_sensors/meshes/orbbec_astra.dae" scale="1.0 1.0 1.0"/>
      </geometry>
    </visual>
    <collision>
      <origin rpy="0 0 0" xyz="0.0 0.0 0.0"/>
      <geometry>
        <box size="0.0730 .2760 0.0720"/>
      </geometry>
    </collision>
    <inertial>
      <mass value="0.01"/>
      <origin xyz="0 0 0"/>
      <inertia ixx="0.001" ixy="0.0" ixz="0.0" iyy="0.001" iyz="0.0" izz="0.001"/>
    </inertial>
  </link>
  <joint name="orbbec_astra_head_cam_depth_joint" type="fixed">
    <origin rpy="0 0 0" xyz="0.0 0.025 0.0"/>
    <parent link="orbbec_astra_head_cam_rgb_frame"/>
    <child link="orbbec_astra_head_cam_depth_frame"/>
  </joint>
  <link name="orbbec_astra_head_cam_depth_frame">
    <inertial>
      <mass value="0.01"/>
      <origin xyz="0 0 0"/>
      <inertia ixx="0.001" ixy="0.0" ixz="0.0" iyy="0.001" iyz="0.0" izz="0.001"/>
    </inertial>
  </link>
  <joint name="orbbec_astra_head_cam_depth_optical_joint" type="fixed">
    <origin rpy="-1.57079632679 0 -1.57079632679" xyz="0 0 0"/>
    <parent link="orbbec_astra_head_cam_depth_frame"/>
    <child link="orbbec_astra_head_cam_depth_optical_frame"/>
  </joint>
  <link name="orbbec_astra_head_cam_depth_optical_frame">
    <inertial>
      <mass value="0.001"/>
      <origin xyz="0 0 0"/>
      <inertia ixx="0.0001" ixy="0.0" ixz="0.0" iyy="0.0001" iyz="0.0" izz="0.0001"/>
    </inertial>
  </link>
  <!-- RGBD sensor for simulation, same as Kinect -->
  <gazebo reference="orbbec_astra_head_cam_depth_frame">
    <sensor name="cam" type="depth">
      <always_on>true</always_on>
      <update_rate>20.0</update_rate>
      <camera>
        <horizontal_fov>1.0471975512</horizontal_fov>
        <image>
          <format>R8G8B8</format>
          <width>640</width>
          <height>480</height>
        </image>
        <clip>
          <near>0.05</near>
          <far>3.5</far>
        </clip>
      </camera>
      <plugin filename="libgazebo_ros_openni_kinect.so" name="xtion_pro_cam_controller">
        <cameraName>orbbec_astra_head</cameraName>
        <alwaysOn>true</alwaysOn>
        <updateRate>15</updateRate>
        <imageTopicName>rgb/image_raw</imageTopicName>
        <depthImageTopicName>depth/image_raw</depthImageTopicName>
        <pointCloudTopicName>depth/points</pointCloudTopicName>
        <cameraInfoTopicName>rgb/camera_info</cameraInfoTopicName>
        <depthImageCameraInfoTopicName>depth/camera_info</depthImageCameraInfoTopicName>
        <frameName>orbbec_astra_head_cam_depth_optical_frame</frameName>
        <baseline>0.1</baseline>
        <distortion_k1>0.0</distortion_k1>
        <distortion_k2>0.0</distortion_k2>
        <distortion_k3>0.0</distortion_k3>
        <distortion_t1>0.0</distortion_t1>
        <distortion_t2>0.0</distortion_t2>
        <pointCloudCutoff>0.4</pointCloudCutoff>
      </plugin>
    </sensor>
  </gazebo>
  <!-- Gazebo ros control plugins -->
  <!-- xacro:ros_control/ -->
  <!-- Import all available sensors -->
  <!-- This file unifies all sensors that can be used on simulation, defined as xacro:macros -->
  <!-- Axis p5512 -->
  <!-- Axis m5013 -->
  <!-- Fotonic -->
  <!-- GPS -->
  <!-- Hokuyo urg04lx -->
  <!-- Hokuyo utm30lx -->
  <!-- Hokuyo ust10lx -->
  <!-- Imu -->
  <!-- Kinect -->
  <!-- Asus Xtion PRO -->
  <!-- Xacro properties -->
  <!-- xacro:property name="M_SCALE" value="0.001"/ -->
  z
  
  <!-- Hokuyo 3d -->
  <!-- Sick s3000 -->
  <!-- KinectV2 -->
  <!-- Orbbec Astra -->
  <!-- Xacro properties -->
  <!-- RGB sensor - cam -->
  <!-- IR sensor - depth -->
  <!-- Import Mico Arm -->
  <!-- ***************** -->
  <!-- Imported elements -->
  <!-- ***************** -->
  <!-- First we import all posible elements defined in the urdf.xacro files. All these elements are defined as macro:xacros -->
  <!-- Import MICO arm elements -->
  <!-- xacro:property name="j2_upper_limit" value="0.0"/ -->
  <!-- xacro:property name="joint_finger_1" value="jaco2_joint_finger_1" / -->
  <!-- xacro:property name="joint_finger_2" value="jaco2_joint_finger_2" / -->
  <!-- xacro:property name="joint_finger_3" value="jaco2_joint_finger_3" / -->
  <!-- 
  <property name="link_end_effector"   value="mico_end_effector" />
  <property name="end_effector_offset" value="0.160" / -->
  <!-- ros control plugin -->
  <!-- Import all available sensors -->
  <!-- xacro:include filename="$(find mico_description)/urdf/sensors/all_sensors.urdf.xacro" / -->
  <!-- ***************** -->
  <!-- Global parameters -->
  <!-- ***************** -->
  <!-- Flag to select the high or low quality model -->
  <!-- mico arm -->
  <!-- Robot mechanical and motor parameters -->
  <xacro:property name="PI" value="3.1415926535897931"/>
  <!-- base_link -->
  <link name="mico_link_base">
    <inertial>
      <mass value="0.506"/>
      <origin xyz="-0.05161 0 -0.003"/>
      <inertia ixx="0.0014526484" ixy="0.0" ixz="-8.792613e-005" iyx="0.0" iyy="0.0018217854" iyz="0.0" izz="0.0008987159"/>
    </inertial>
    <visual>
      <origin rpy="0 0 0" xyz="0 0 0"/>
      <geometry>
        <mesh filename="package://mico_description/meshes/arms/mico_link_base.dae"/>
      </geometry>
      <material name="carbon_fiber">
        <color rgba="0.792156862745098 0.819607843137255 0.933333333333333 1"/>
      </material>
    </visual>
    <collision>
      <origin rpy="0 0 0 " xyz="0 0 0"/>
      <geometry>
        <mesh filename="package://mico_description/meshes/arms/mico_link_base.dae"/>
      </geometry>
    </collision>
  </link>
  <!-- LINK 1 -->
  <link name="mico_link_1">
    <inertial>
      <mass value="0.7"/>
      <origin xyz="0.07155 0.00229 -0.00028"/>
      <inertia ixx="0.0018430902" ixy="0.0001075379" ixz="2.683183e-005" iyy="0.0023530852" iyz="4.5192e-007" izz="0.0016327528"/>
    </inertial>
    <visual>
      <origin rpy="0 0 0" xyz="0 0 0"/>
      <geometry>
        <mesh filename="package://mico_description/meshes/arms/mico_link_1.dae"/>
      </geometry>
      <material name="carbon_fiber">
        <color rgba="0.792156862745098 0.819607843137255 0.933333333333333 1"/>
      </material>
    </visual>
    <collision>
      <origin rpy="0 0 0 " xyz="0 0 0"/>
      <geometry>
        <mesh filename="package://mico_description/meshes/arms/mico_link_1.dae"/>
      </geometry>
    </collision>
  </link>
  <joint name="mico_joint_1" type="revolute">
    <origin rpy="3.14159265359 0.0 3.14159265359" xyz="0 0 0.1535"/>
    <parent link="mico_link_base"/>
    <child link="mico_link_1"/>
    <axis xyz="0 0 -1"/>
    <limit effort="60.0" lower="-3.13" upper="3.13" velocity="2.9217"/>
    <dynamics damping="0.7" friction="0.5"/>
  </joint>
  <transmission name="j1_trans">
    <type>transmission_interface/SimpleTransmission</type>
    <joint name="mico_joint_1">
      <hardwareInterface>EffortJointInterface</hardwareInterface>
    </joint>
    <actuator name="j1_motor">
      <hardwareInterface>EffortJointInterface</hardwareInterface>
      <mechanicalReduction>1.0</mechanicalReduction>
      <motorTorqueConstant>50.0</motorTorqueConstant>
    </actuator>
  </transmission>
  <!-- LINK 2 -->
  <link name="mico_link_2">
    <inertial>
      <mass value="0.429"/>
      <origin xyz="0.06076 0 -0.00014"/>
      <inertia ixx="0.0011551458" ixy="-6.3e-010" ixz="2.519546e-005" iyy="0.0015754353" iyz="-7.6e-010" izz="0.0007798411"/>
    </inertial>
    <visual>
      <origin rpy="0 0 0" xyz="0 0 0"/>
      <geometry>
        <mesh filename="package://mico_description/meshes/arms/mico_link_2.dae"/>
      </geometry>
      <material name="carbon_fiber">
        <color rgba="0.792156862745098 0.819607843137255 0.933333333333333 1"/>
      </material>
    </visual>
    <collision>
      <origin rpy="0 0 0 " xyz="0 0 0"/>
      <geometry>
        <mesh filename="package://mico_description/meshes/arms/mico_link_2.dae"/>
      </geometry>
    </collision>
  </link>
  <joint name="mico_joint_2" type="revolute">
    <origin rpy="-1.57079632679 3.14159265359 0.0" xyz="0 0 -0.1185"/>
    <parent link="mico_link_1"/>
    <child link="mico_link_2"/>
    <axis xyz="0 0 1"/>
    <limit effort="60.0" lower="-3.13" upper="0.785398163397" velocity="2.9217"/>
    <dynamics damping="0.7" friction="0.5"/>
  </joint>
  <transmission name="j2_trans">
    <type>transmission_interface/SimpleTransmission</type>
    <joint name="mico_joint_2">
      <hardwareInterface>EffortJointInterface</hardwareInterface>
    </joint>
    <actuator name="j2_motor">
      <hardwareInterface>EffortJointInterface</hardwareInterface>
      <mechanicalReduction>1.0</mechanicalReduction>
      <motorTorqueConstant>50.0</motorTorqueConstant>
    </actuator>
  </transmission>
  <!-- LINK 3 -->
  <link name="mico_link_3">
    <inertial>
      <mass value="0.351"/>
      <origin xyz="-0.07306 0 -0.00466"/>
      <inertia ixx="0.0003749308" ixy="0.0" ixz="-0.0001258961" iyy="0.0010047174" iyz="0.0" izz="0.0009318091"/>
    </inertial>
    <visual>
      <origin rpy="0 0 0" xyz="0 0 0"/>
      <geometry>
        <mesh filename="package://mico_description/meshes/arms/mico_link_3.dae"/>
      </geometry>
      <material name="carbon_fiber">
        <color rgba="0.792156862745098 0.819607843137255 0.933333333333333 1"/>
      </material>
    </visual>
    <collision>
      <origin rpy="0 0 0 " xyz="0 0 0"/>
      <geometry>
        <mesh filename="package://mico_description/meshes/arms/mico_link_3.dae"/>
      </geometry>
    </collision>
  </link>
  <joint name="mico_joint_3" type="revolute">
    <origin rpy="3.14159265359 0.0 1.57079632679" xyz="0.29 0 0"/>
    <parent link="mico_link_2"/>
    <child link="mico_link_3"/>
    <axis xyz="0 0 -1"/>
    <limit effort="60.0" lower="-3.92699081699" upper="0.785398163397" velocity="2.9217"/>
    <dynamics damping="0.7" friction="0.5"/>
  </joint>
  <transmission name="j3_trans">
    <type>transmission_interface/SimpleTransmission</type>
    <joint name="mico_joint_3">
      <hardwareInterface>EffortJointInterface</hardwareInterface>
    </joint>
    <actuator name="j3_motor">
      <hardwareInterface>EffortJointInterface</hardwareInterface>
      <mechanicalReduction>1.0</mechanicalReduction>
      <motorTorqueConstant>50.0</motorTorqueConstant>
    </actuator>
  </transmission>
  <!-- LINK 4 -->
  <link name="mico_link_4">
    <inertial>
      <mass value="0.429"/>
      <origin xyz="0.06076 0 -0.00014"/>
      <inertia ixx="0.0011551458" ixy="-6.3e-010" ixz="2.519546e-005" iyy="0.0015754353" iyz="-7.6e-010" izz="0.0007798411"/>
    </inertial>
    <visual>
      <origin rpy="0 0 0" xyz="0 0 0"/>
      <geometry>
        <mesh filename="package://mico_description/meshes/arms/mico_link_4.dae"/>
      </geometry>
      <material name="carbon_fiber">
        <color rgba="0.792156862745098 0.819607843137255 0.933333333333333 1"/>
      </material>
    </visual>
    <collision>
      <origin rpy="0 0 0 " xyz="0 0 0"/>
      <geometry>
        <mesh filename="package://mico_description/meshes/arms/mico_link_4.dae"/>
      </geometry>
    </collision>
  </link>
  <joint name="mico_joint_4" type="revolute">
    <origin rpy="3.14159265359 1.57079632679 0.0" xyz="0.123 0 -0.00845"/>
    <parent link="mico_link_3"/>
    <child link="mico_link_4"/>
    <axis xyz="0 0 -1"/>
    <limit effort="60.0" lower="-3.13" upper="3.13" velocity="2.9217"/>
    <dynamics damping="0.7" friction="0.5"/>
  </joint>
  <transmission name="j4_trans">
    <type>transmission_interface/SimpleTransmission</type>
    <joint name="mico_joint_4">
      <hardwareInterface>EffortJointInterface</hardwareInterface>
    </joint>
    <actuator name="j4_motor">
      <hardwareInterface>EffortJointInterface</hardwareInterface>
      <mechanicalReduction>1.0</mechanicalReduction>
      <motorTorqueConstant>5.0</motorTorqueConstant>
    </actuator>
  </transmission>
  <!-- LINK 5 -->
  <link name="mico_link_5">
    <inertial>
      <mass value="0.429"/>
      <origin xyz="0.06076 0 -0.00014"/>
      <inertia ixx="0.0011551458" ixy="-6.3e-010" ixz="2.519546e-005" iyy="0.0015754353" iyz="-7.6e-010" izz="0.0007798411"/>
    </inertial>
    <visual>
      <origin rpy="0 0 0" xyz="0 0 0"/>
      <geometry>
        <mesh filename="package://mico_description/meshes/arms/mico_link_5.dae"/>
      </geometry>
      <material name="carbon_fiber">
        <color rgba="0.792156862745098 0.819607843137255 0.933333333333333 1"/>
      </material>
    </visual>
    <collision>
      <origin rpy="0 0 0 " xyz="0 0 0"/>
      <geometry>
        <mesh filename="package://mico_description/meshes/arms/mico_link_5.dae"/>
      </geometry>
    </collision>
  </link>
  <joint name="mico_joint_5" type="revolute">
    <origin rpy="0 -1.0471975512 0.0" xyz="0.037 0 -0.06408"/>
    <parent link="mico_link_4"/>
    <child link="mico_link_5"/>
    <axis xyz="0 0 -1"/>
    <limit effort="60.0" lower="-3.13" upper="3.13" velocity="2.9217"/>
    <dynamics damping="0.7" friction="0.5"/>
  </joint>
  <transmission name="j5_trans">
    <type>transmission_interface/SimpleTransmission</type>
    <joint name="mico_joint_5">
      <hardwareInterface>EffortJointInterface</hardwareInterface>
    </joint>
    <actuator name="j5_motor">
      <hardwareInterface>EffortJointInterface</hardwareInterface>
      <mechanicalReduction>1.0</mechanicalReduction>
      <motorTorqueConstant>5.0</motorTorqueConstant>
    </actuator>
  </transmission>
  <!-- LINK 6 -->
  <link name="mico_link_hand">
    <inertial>
      <mass value="0.429"/>
      <origin xyz="0.06076 0 -0.00014"/>
      <inertia ixx="0.0011551458" ixy="-6.3e-010" ixz="2.519546e-005" iyy="0.0015754353" iyz="-7.6e-010" izz="0.0007798411"/>
    </inertial>
    <visual>
      <origin rpy="0 0 0" xyz="0 0 0"/>
      <geometry>
        <mesh filename="package://mico_description/meshes/arms/jaco2_link_hand.dae"/>
      </geometry>
      <material name="carbon_fiber">
        <color rgba="0.792156862745098 0.819607843137255 0.933333333333333 1"/>
      </material>
    </visual>
    <collision>
      <origin rpy="0 0 0 " xyz="0 0 0"/>
      <geometry>
        <mesh filename="package://mico_description/meshes/arms/jaco2_link_hand.dae"/>
      </geometry>
    </collision>
  </link>
  <joint name="mico_joint_6" type="revolute">
    <origin rpy="-1.0471975512 0.0 1.57079632679" xyz="0.037 0 -0.06408"/>
    <parent link="mico_link_5"/>
    <child link="mico_link_hand"/>
    <axis xyz="0 0 -1"/>
    <limit effort="60.0" lower="-1.52" upper="4.7" velocity="2.9217"/>
    <dynamics damping="0.7" friction="0.5"/>
  </joint>
  <transmission name="j6_trans">
    <type>transmission_interface/SimpleTransmission</type>
    <joint name="mico_joint_6">
      <hardwareInterface>EffortJointInterface</hardwareInterface>
    </joint>
    <actuator name="j6_motor">
      <hardwareInterface>EffortJointInterface</hardwareInterface>
      <mechanicalReduction>1.0</mechanicalReduction>
      <motorTorqueConstant>5.0</motorTorqueConstant>
    </actuator>
  </transmission>
  <!-- LINK FINGER 1 -->
  <link name="mico_link_finger_1">
    <inertial>
      <mass value="0.050"/>
      <origin xyz="0.03 0.03 0.03"/>
      <inertia ixx="0.0011551458" ixy="-6.3e-010" ixz="2.519546e-005" iyy="0.0015754353" iyz="-7.6e-010" izz="0.0007798411"/>
    </inertial>
    <visual>
      <origin rpy="0 0 0" xyz="0 0 0"/>
      <geometry>
        <mesh filename="package://mico_description/meshes/arms/mico_link_finger_1.dae"/>
      </geometry>
      <material name="carbon_fiber">
        <color rgba="0.792156862745098 0.819607843137255 0.933333333333333 1"/>
      </material>
    </visual>
    <collision>
      <origin rpy="0 0 0 " xyz="0 0 0"/>
      <geometry>
        <mesh filename="package://mico_description/meshes/arms/mico_link_finger_1.dae"/>
      </geometry>
    </collision>
  </link>
  <joint name="mico_joint_finger_1" type="revolute">
    <origin rpy="-1.7983 1.117 3.1416" xyz="-0.03978 0 -0.10071"/>
    <parent link="mico_link_hand"/>
    <child link="mico_link_finger_1"/>
    <axis xyz="0 0 1"/>
    <limit effort="60.0" lower="0" upper="0.698131700798" velocity="2.9217"/>
    <dynamics damping="0.7" friction="0.5"/>
  </joint>
  <transmission name="jf1_trans">
    <type>transmission_interface/SimpleTransmission</type>
    <joint name="mico_joint_finger_1">
      <hardwareInterface>EffortJointInterface</hardwareInterface>
    </joint>
    <actuator name="jf1_motor">
      <hardwareInterface>EffortJointInterface</hardwareInterface>
      <mechanicalReduction>1.0</mechanicalReduction>
      <motorTorqueConstant>5.0</motorTorqueConstant>
    </actuator>
  </transmission>
  <!-- LINK FINGER 2 -->
  <link name="mico_link_finger_2">
    <inertial>
      <mass value="0.050"/>
      <origin xyz="0.03 0.03 0.03"/>
      <inertia ixx="0.0011551458" ixy="-6.3e-010" ixz="2.519546e-005" iyy="0.0015754353" iyz="-7.6e-010" izz="0.0007798411"/>
    </inertial>
    <visual>
      <origin rpy="0 0 0" xyz="0 0 0"/>
      <geometry>
        <mesh filename="package://mico_description/meshes/arms/mico_link_finger_2.dae"/>
      </geometry>
      <material name="carbon_fiber">
        <color rgba="0.792156862745098 0.819607843137255 0.933333333333333 1"/>
      </material>
    </visual>
    <collision>
      <origin rpy="0 0 0 " xyz="0 0 0"/>
      <geometry>
        <mesh filename="package://mico_description/meshes/arms/mico_link_finger_2.dae"/>
      </geometry>
    </collision>
  </link>
  <joint name="mico_joint_finger_2" type="revolute">
    <origin rpy="-1.6222 1.117 -0.23615" xyz="0.03569 -0.0216 -0.10071"/>
    <parent link="mico_link_hand"/>
    <child link="mico_link_finger_2"/>
    <axis xyz="0 0 1"/>
    <limit effort="60.0" lower="0" upper="0.698131700798" velocity="2.9217"/>
    <dynamics damping="0.7" friction="0.5"/>
  </joint>
  <transmission name="jf2_trans">
    <type>transmission_interface/SimpleTransmission</type>
    <joint name="mico_joint_finger_2">
      <hardwareInterface>EffortJointInterface</hardwareInterface>
    </joint>
    <actuator name="jf2_motor">
      <hardwareInterface>EffortJointInterface</hardwareInterface>
      <mechanicalReduction>1.0</mechanicalReduction>
      <motorTorqueConstant>5.0</motorTorqueConstant>
    </actuator>
  </transmission>
  <!-- LINK FINGER 3 -->
  <link name="mico_link_finger_3">
    <inertial>
      <mass value="0.050"/>
      <origin xyz="0.03 0.03 0.03"/>
      <inertia ixx="0.0011551458" ixy="-6.3e-010" ixz="2.519546e-005" iyy="0.0015754353" iyz="-7.6e-010" izz="0.0007798411"/>
    </inertial>
    <visual>
      <origin rpy="0 0 0" xyz="0 0 0"/>
      <geometry>
        <mesh filename="package://mico_description/meshes/arms/mico_link_finger_3.dae"/>
      </geometry>
      <material name="carbon_fiber">
        <color rgba="0.792156862745098 0.819607843137255 0.933333333333333 1"/>
      </material>
    </visual>
    <collision>
      <origin rpy="0 0 0 " xyz="0 0 0"/>
      <geometry>
        <mesh filename="package://mico_description/meshes/arms/mico_link_finger_3.dae"/>
      </geometry>
    </collision>
  </link>
  <joint name="mico_joint_finger_3" type="revolute">
    <origin rpy="-1.5161 1.1459 0.23978" xyz="0.03569 0.0216 -0.10071"/>
    <parent link="mico_link_hand"/>
    <child link="mico_link_finger_3"/>
    <axis xyz="0 0 1"/>
    <limit effort="60.0" lower="0" upper="0.698131700798" velocity="2.9217"/>
    <dynamics damping="0.7" friction="0.5"/>
  </joint>
  <transmission name="jf3_trans">
    <type>transmission_interface/SimpleTransmission</type>
    <joint name="mico_joint_finger_3">
      <hardwareInterface>EffortJointInterface</hardwareInterface>
    </joint>
    <actuator name="jf3_motor">
      <hardwareInterface>EffortJointInterface</hardwareInterface>
      <mechanicalReduction>1.0</mechanicalReduction>
      <motorTorqueConstant>5.0</motorTorqueConstant>
    </actuator>
  </transmission>
  <!-- Gazebo ros control plugins -->
  <!-- xacro:ros_control/ -->
  <!-- Fix torso to base -->
  <joint name="j_base_torso" type="fixed">
    <origin rpy="0.0 0.0 0.0" xyz="-0.133 0.0 0.213"/>
    <parent link="base_link"/>
    <child link="base_link_rb1_torso"/>
    <axis xyz="0 0 0"/>
  </joint>
  <!-- Fix arm to torso -->
  <joint name="j_torso_arm" type="fixed">
    <!--origin
      xyz="0.055 0.0 0.0755"
      rpy="0.0 0.0 0.0" / -->
    <origin rpy="0.0 0.0 0.0" xyz="0.055 0.0 0.010"/>
    <parent link="link2_torso"/>
    <child link="mico_link_base"/>
    <axis xyz="0 0 0"/>
  </joint>
  <!-- Gazebo ros control pluggins -->
  <!-- xacro:ros_control/ -->
</robot>

